Workbook

Sheet Budget 2026
A1: Topix.dk ApS — Budget 2026
A2: Resultatopgørelse. Jan–jul = faktiske tal, aug–dec = budget. Alle beløb i DKK ekskl. moms. Forudbetalte forløb er periodiseret over aftaleperioden.
B3: FAKTISK | I3: BUDGET
B4: Jan | C4: Feb | D4: Mar | E4: Apr | F4: Maj | G4: Jun | H4: Jul | I4: Aug | J4: Sep | K4: Okt | L4: Nov | M4: Dec | N4: I alt 2026
A6: OMSÆTNING
A7: Løbende medlemsabonnement | B7: =Omsætning!B21 -> 43030.56 | C7: =Omsætning!C21 -> 50030.56 | D7: =Omsætning!D21 -> 63000 | E7: =Omsætning!E21 -> 70875 | F7: =Omsætning!F21 -> 70437.5 | G7: =Omsætning!G21 -> 70437.5 | H7: =Omsætning!H21 -> 63437.5 | I7: =Omsætning!I21 -> 68663.194 | ... M7: =Omsætning!M21 -> 88792.614 | N7: =SUM(B7:M7) -> 825217.31
A8: Periodiseret fuldbetaling — solgt i 2025 | B8: =Omsætning!B22 -> 38620.833 | C8: =Omsætning!C22 -> 38620.833 | D8: =Omsætning!D22 -> 38620.833 | E8: =Omsætning!E22 -> 20287.5 | F8: =Omsætning!F22 -> 14454.167 | G8: =Omsætning!G22 -> 11120.833 | H8: =Omsætning!H22 -> 11120.833 | I8: =Omsætning!I22 -> 7787.5 | ... M8: =Omsætning!M22 -> 0 | N8: =SUM(B8:M8) -> 186466.67
A9: Periodiseret fuldbetaling — solgt i 2026 | B9: =Omsætning!B23 -> 4166.6667 | C9: =Omsætning!C23 -> 7500 | D9: =Omsætning!D23 -> 10417.5 | E9: =Omsætning!E23 -> 10417.5 | F9: =Omsætning!F23 -> 19584.167 | G9: =Omsætning!G23 -> 25000.833 | H9: =Omsætning!H23 -> 25000.833 | I9: =Omsætning!I23 -> 26667.5 | ... M9: =Omsætning!M23 -> 26667.5 | N9: =SUM(B9:M9) -> 235425
A10: Periodiseret fuldbetaling — budgetteret nysalg | B10: =Omsætning!B24 -> 0 | C10: =Omsætning!C24 -> 0 | D10: =Omsætning!D24 -> 0 | E10: =Omsætning!E24 -> 0 | F10: =Omsætning!F24 -> 0 | G10: =Omsætning!G24 -> 0 | H10: =Omsætning!H24 -> 0 | I10: =Omsætning!I24 -> 0 | ... M10: =Omsætning!M24 -> 16666.667 | N10: =SUM(B10:M10) -> 41666.667
A11: Konsulent & øvrig omsætning | B11: =Omsætning!B25 -> 0 | C11: =Omsætning!C25 -> 0 | D11: =Omsætning!D25 -> 0 | E11: =Omsætning!E25 -> 2525 | F11: =Omsætning!F25 -> 12772.24 | G11: =Omsætning!G25 -> 1000 | H11: =Omsætning!H25 -> 0 | I11: =Omsætning!I25 -> 2500 | ... M11: =Omsætning!M25 -> 2500 | N11: =SUM(B11:M11) -> 28797.24
A12: OMSÆTNING I ALT | B12: =SUM(B7:B11) -> 85818.06 | C12: =SUM(C7:C11) -> 96151.393 | D12: =SUM(D7:D11) -> 112038.33 | E12: =SUM(E7:E11) -> 104105 | F12: =SUM(F7:F11) -> 117248.07 | G12: =SUM(G7:G11) -> 107559.17 | H12: =SUM(H7:H11) -> 99559.167 | I12: =SUM(I7:I11) -> 105618.19 | ... M12: =SUM(M7:M11) -> 134626.78 | N12: =SUM(B12:M12) -> 1317572.9
A14: OMKOSTNINGER
A15: Direkte Omkostninger | B15: =Omkostninger!B11 -> 32100 | C15: =Omkostninger!C11 -> 59800 | D15: =Omkostninger!D11 -> 65280.64 | E15: =Omkostninger!E11 -> 26250 | F15: =Omkostninger!F11 -> 12525 | G15: =Omkostninger!G11 -> 74690 | H15: =Omkostninger!H11 -> 22325 | I15: =Omkostninger!I11 -> 41888 | ... M15: =Omkostninger!M11 -> 41888 | N15: =SUM(B15:M15) -> 502410.64
A16: Salg & Marketing | B16: =Omkostninger!B16 -> 421.92 | C16: =Omkostninger!C16 -> 5175.33 | D16: =Omkostninger!D16 -> 546.11 | E16: =Omkostninger!E16 -> 6170.52 | F16: =Omkostninger!F16 -> 19506.94 | G16: =Omkostninger!G16 -> 14828.16 | H16: =Omkostninger!H16 -> 2023.42 | I16: =Omkostninger!I16 -> 6954 | ... M16: =Omkostninger!M16 -> 6954 | N16: =SUM(B16:M16) -> 83442.4
A17: Software & It | B17: =Omkostninger!B23 -> 10175.51 | C17: =Omkostninger!C23 -> 7739.56 | D17: =Omkostninger!D23 -> 7760.85 | E17: =Omkostninger!E23 -> 7862.9 | F17: =Omkostninger!F23 -> 1988.76 | G17: =Omkostninger!G23 -> 5055.42 | H17: =Omkostninger!H23 -> 4116.24 | I17: =Omkostninger!I23 -> 6108 | ... M17: =Omkostninger!M23 -> 6108 | N17: =SUM(B17:M17) -> 75239.24
A18: Personale | B18: =Omkostninger!B29 -> 26436.8 | C18: =Omkostninger!C29 -> 29901 | D18: =Omkostninger!D29 -> 25379.89 | E18: =Omkostninger!E29 -> 38941.43 | F18: =Omkostninger!F29 -> 19926 | G18: =Omkostninger!G29 -> 36475.21 | H18: =Omkostninger!H29 -> 41558.74 | I18: =Omkostninger!I29 -> 31238 | ... M18: =Omkostninger!M29 -> 31238 | N18: =SUM(B18:M18) -> 374809.07
A19: Lokale & Administration | B19: =Omkostninger!B40 -> 4474.74 | C19: =Omkostninger!C40 -> 4292.61 | D19: =Omkostninger!D40 -> 25291.83 | E19: =Omkostninger!E40 -> 4144.24 | F19: =Omkostninger!F40 -> 6847.25 | G19: =Omkostninger!G40 -> 4241.44 | H19: =Omkostninger!H40 -> 3486.66 | I19: =Omkostninger!I40 -> 4371 | ... M19: =Omkostninger!M40 -> 4371 | N19: =SUM(B19:M19) -> 74633.77
A20: OMKOSTNINGER I ALT | B20: =B15+B16+B17+B18+B19 -> 73608.97 | C20: =C15+C16+C17+C18+C19 -> 106908.5 | D20: =D15+D16+D17+D18+D19 -> 124259.32 | E20: =E15+E16+E17+E18+E19 -> 83369.09 | F20: =F15+F16+F17+F18+F19 -> 60793.95 | G20: =G15+G16+G17+G18+G19 -> 135290.23 | H20: =H15+H16+H17+H18+H19 -> 73510.06 | I20: =I15+I16+I17+I18+I19 -> 90559 | ... M20: =M15+M16+M17+M18+M19 -> 90559 | N20: =SUM(B20:M20) -> 1110535.1
A22: RESULTAT FØR SKAT | B22: =B12-B20 -> 12209.09 | C22: =C12-C20 -> -10757.107 | D22: =D12-D20 -> -12220.987 | E22: =E12-E20 -> 20735.91 | F22: =F12-F20 -> 56454.123 | G22: =G12-G20 -> -27731.063 | H22: =H12-H20 -> 26049.107 | I22: =I12-I20 -> 15059.194 | ... M22: =M12-M20 -> 44067.78 | N22: =SUM(B22:M22) -> 207037.77
A23: Overskudsgrad | B23: =IF(B12=0,0,B22/B12) -> 0.14226714 | C23: =IF(C12=0,0,C22/C12) -> -0.11187676 | D23: =IF(D12=0,0,D22/D12) -> -0.10907862 | E23: =IF(E12=0,0,E22/E12) -> 0.19918265 | F23: =IF(F12=0,0,F22/F12) -> 0.48149297 | G23: =IF(G12=0,0,G22/G12) -> -0.25782148 | H23: =IF(H12=0,0,H22/H12) -> 0.26164448 | I23: =IF(I12=0,0,I22/I12) -> 0.14258144 | ... N23: =IF(N12=0,0,N22/N12) -> 0.15713572
A24: Akkumuleret resultat | B24: =B22 -> 12209.09 | C24: =B24+C22 -> 1451.9833 | D24: =C24+D22 -> -10769.003 | E24: =D24+E22 -> 9966.9067 | F24: =E24+F22 -> 66421.03 | G24: =F24+G22 -> 38689.967 | H24: =G24+H22 -> 64739.073 | I24: =H24+I22 -> 79798.268 | J24: =I24+J22 -> 102206.11 | ... M24: =L24+M22 -> 207037.77
A26: NØGLETAL
A27: Aktive løbende medlemmer, ultimo | B27: =Omsætning!B10 -> 13 | C27: =Omsætning!C10 -> 15 | D27: =Omsætning!D10 -> 17 | E27: =Omsætning!E10 -> 20 | F27: =Omsætning!F10 -> 20 | G27: =Omsætning!G10 -> 20 | H27: =Omsætning!H10 -> 18 | I27: =Omsætning!I10 -> 19 | ... M27: =Omsætning!M10 -> 23 | N27: =M27 -> 23
A28: MRR, ultimo (ekskl. moms) | B28: =Omsætning!B18 -> 43030.56 | C28: =Omsætning!C18 -> 50030.56 | D28: =Omsætning!D18 -> 63000 | E28: =Omsætning!E18 -> 70875 | F28: =Omsætning!F18 -> 70437.5 | G28: =Omsætning!G18 -> 70437.5 | H28: =Omsætning!H18 -> 63437.5 | I28: =Omsætning!I18 -> 68663.194 | ... M28: =Omsætning!M18 -> 88792.614 | N28: =M28 -> 88792.614
A29: ARR, ultimo (MRR x 12) | B29: =B28*12 -> 516366.72 | C29: =C28*12 -> 600366.72 | D29: =D28*12 -> 756000 | E29: =E28*12 -> 850500 | F29: =F28*12 -> 845250 | G29: =G28*12 -> 845250 | H29: =H28*12 -> 761250 | I29: =I28*12 -> 823958.33 | ... M29: =M28*12 -> 1065511.4 | N29: =M29 -> 1065511.4
A31: Farvekode: blå = indtastet tal · sort = formel · grøn = hentet fra andet ark · gul = styringsgreb.
A32: Omsætningen er periodiseret. Likviditeten afviger, fordi forudbetalte forløb indbetales på én gang — se arket Periodisering, kolonne V.

Sheet Forudsætninger
A1: Topix.dk ApS — Budget 2026
A2: Forudsætninger og styringsgreb. Alle beløb i DKK ekskl. moms.
A4: GRUNDLAG
A5: Faktisk periode (antal måneder med realiserede tal) | B5: 7 | C5: Jan–jul 2026. Aug–dec er budget.
A6: Momssats | B6: 0.25 | C6: Alle tal i modellen er ekskl. moms.
A8: LØBENDE MEDLEMSKAB (månedsabonnement)
A9: Aktive løbende medlemmer, ultimo juli 2026 | B9: 18 | C9: Faktisk optalt: unikke betalere i Stripe i juli.
A10: MRR ultimo juli 2026, ekskl. moms | B10: 63437.5 | C10: Faktisk Stripe-abonnementsomsætning juli.
A11: Gns. pris pr. eksisterende medlem, ekskl. moms/md | B11: =B10/B9 -> 3524.3056 | C11: Blandet pris: 3.500 (gl.), 4.375 (ny) og én rabataftale.
A12: Listepris nyt medlem, ekskl. moms/md | B12: 4375 | C12: Aktuel pris (5.468,75 inkl. moms).
A13: Nye løbende medlemmer pr. måned (aug–dec) | B13: 2 | C13: ANTAGELSE. Faktisk feb–jul: 2,0 nye pr. måned.
A14: Opsigelser pr. måned (aug–dec) | B14: 1 | C14: ANTAGELSE. Faktisk feb–jul: 1,2 opsigelser pr. måned.
A16: FULDBETALING (forudbetalt forløb)
A17: Pris pr. fuldbetaling, ekskl. moms | B17: 50000 | C17: 62.500 inkl. moms. 2025-prisen var 30.000–40.000 ekskl. moms.
A18: Nye fuldbetalinger pr. måned (sep–dec) | B18: 1 | C18: ANTAGELSE. Faktisk jan–aug 2026: 8 stk. = 1,0 pr. måned.
A19: Standard periodiseringsperiode, måneder | B19: 12 | C19: Sættes pr. kontrakt i arket Periodisering, kolonne F.
A21: ØVRIG OMSÆTNING
A22: Konsulent & øvrig omsætning pr. måned (aug–dec) | B22: 2500 | C22: ANTAGELSE. Faktisk jan–jul: 16.297 i alt = 2.328/md.
A24: GEBYRER
A25: Stripe-gebyr i pct. af Stripe-omsætning | B25: 0.0239 | C25: Faktisk jan–jul 2026: 16.058 kr. af 672.061 kr. brutto.
A27: NOTER TIL GRUNDDATA
A28: Kilder: Arkiv.xlsx (e-conomic, alle fakturaer apr. 2025 – aug. 2026), unified_payments__1_.csv (Stripe,
A29: hele historikken), default.csv (bankkonto 9042865505), original.csv (betalte leverandørfakturaer),
A30: export_2026-01-01_2026-12-31.csv (Pleo-kort).
A32: AFSTEMNING AF E-CONOMIC-ARKIVET:
A33: · 138 fakturaer i alt. 68 af dem er testfakturaer (Jonas firma, Jonas TEST, Jonas' firma, Sebastian
A34: Salinas) — de går i nul efter kreditnotaer og er holdt helt ude.
A35: · 4 kunder er fuldt krediteret og indgår ikke: MD-Booking I/S, Von Sperling ApS, Smag & Slægt ApS
A36: og Brick Works (sidstnævnte gik i stedet på månedsabonnement fra april 2026).
A37: · Netto reel fakturering: 880.915 kr. inkl. moms.
A38: · Fakturaer der modsvarer en Stripe-betaling er kun talt én gang: Rally Support, Brilleværk (2025),
A39: Olsen & Kompagni og YKRG. De to sidste er månedsabonnementer og ligger i MRR-linjen, ikke her.
... A47: Eventuel pension og ATP indgår ikke, hvis den ikke er betalt fra denne konto.

Sheet Periodisering
A1: Periodisering af forudbetalte forløb
A2: Hver kontrakt indtægtsføres lineært fra og med faktura-/betalingsmåneden. Antal måneder i kolonne F kan rettes pr. linje. Beløb ekskl. moms.
A4: Kunde | B4: Dato | C4: Kilde | D4: Beløb inkl. moms | E4: Beløb ekskl. moms | F4: Antal mdr. | G4: Startindeks | H4: Jan | I4: Feb | J4: Mar | K4: Apr | L4: Maj | M4: Jun | N4: Jul | O4: Aug | P4: Sep | Q4: Okt | R4: Nov | S4: Dec | T4: I alt 2026 | U4: Indregnet 2025 | V4: Overført til 2027+
A5: SOLGT I 2025
A6: Wrizz ApS | B6: 45758 | C6: Faktura | D6: 18750 | E6: =D6/(1+Forudsætninger!$B$6) -> 15000 | F6: 12 | G6: =(YEAR(B6)-2026)*12+MONTH(B6) -> -8 | H6: =IF(AND(1>=$G6,1<=$G6+$F6-1),$E6/$F6,0) -> 1250 | I6: =IF(AND(2>=$G6,2<=$G6+$F6-1),$E6/$F6,0) -> 1250 | J6: =IF(AND(3>=$G6,3<=$G6+$F6-1),$E6/$F6,0) -> 1250 | K6: =IF(AND(4>=$G6,4<=$G6+$F6-1),$E6/$F6,0) -> 0 | L6: =IF(AND(5>=$G6,5<=$G6+$F6-1),$E6/$F6,0) -> 0 | M6: =IF(AND(6>=$G6,6<=$G6+$F6-1),$E6/$F6,0) -> 0 | N6: =IF(AND(7>=$G6,7<=$G6+$F6-1),$E6/$F6,0) -> 0 | O6: =IF(AND(8>=$G6,8<=$G6+$F6-1),$E6/$F6,0) -> 0 | P6: =IF(AND(9>=$G6,9<=$G6+$F6-1),$E6/$F6,0) -> 0 | Q6: =IF(AND(10>=$G6,10<=$G6+$F6-1),$E6/$F6,0) -> 0 | R6: =IF(AND(11>=$G6,11<=$G6+$F6-1),$E6/$F6,0) -> 0 | S6: =IF(AND(12>=$G6,12<=$G6+$F6-1),$E6/$F6,0) -> 0 | T6: =SUM(H6:S6) -> 3750 | U6: =$E6/$F6*MAX(0,MIN($F6,1-$G6)) -> 11250 | V6: =E6-T6-U6 -> 0
A7: D.A.S. GRUPPEN A/S | B7: 45761 | C7: Faktura | D7: 37500 | E7: =D7/(1+Forudsætninger!$B$6) -> 30000 | F7: 12 | G7: =(YEAR(B7)-2026)*12+MONTH(B7) -> -8 | H7: =IF(AND(1>=$G7,1<=$G7+$F7-1),$E7/$F7,0) -> 2500 | I7: =IF(AND(2>=$G7,2<=$G7+$F7-1),$E7/$F7,0) -> 2500 | J7: =IF(AND(3>=$G7,3<=$G7+$F7-1),$E7/$F7,0) -> 2500 | K7: =IF(AND(4>=$G7,4<=$G7+$F7-1),$E7/$F7,0) -> 0 | L7: =IF(AND(5>=$G7,5<=$G7+$F7-1),$E7/$F7,0) -> 0 | M7: =IF(AND(6>=$G7,6<=$G7+$F7-1),$E7/$F7,0) -> 0 | N7: =IF(AND(7>=$G7,7<=$G7+$F7-1),$E7/$F7,0) -> 0 | O7: =IF(AND(8>=$G7,8<=$G7+$F7-1),$E7/$F7,0) -> 0 | P7: =IF(AND(9>=$G7,9<=$G7+$F7-1),$E7/$F7,0) -> 0 | Q7: =IF(AND(10>=$G7,10<=$G7+$F7-1),$E7/$F7,0) -> 0 | R7: =IF(AND(11>=$G7,11<=$G7+$F7-1),$E7/$F7,0) -> 0 | S7: =IF(AND(12>=$G7,12<=$G7+$F7-1),$E7/$F7,0) -> 0 | T7: =SUM(H7:S7) -> 7500 | U7: =$E7/$F7*MAX(0,MIN($F7,1-$G7)) -> 22500 | V7: =E7-T7-U7 -> 0
A8: FRTFV ApS | B8: 45761 | C8: Faktura | D8: 37500 | E8: =D8/(1+Forudsætninger!$B$6) -> 30000 | F8: 12 | G8: =(YEAR(B8)-2026)*12+MONTH(B8) -> -8 | H8: =IF(AND(1>=$G8,1<=$G8+$F8-1),$E8/$F8,0) -> 2500 | I8: =IF(AND(2>=$G8,2<=$G8+$F8-1),$E8/$F8,0) -> 2500 | J8: =IF(AND(3>=$G8,3<=$G8+$F8-1),$E8/$F8,0) -> 2500 | K8: =IF(AND(4>=$G8,4<=$G8+$F8-1),$E8/$F8,0) -> 0 | L8: =IF(AND(5>=$G8,5<=$G8+$F8-1),$E8/$F8,0) -> 0 | M8: =IF(AND(6>=$G8,6<=$G8+$F8-1),$E8/$F8,0) -> 0 | N8: =IF(AND(7>=$G8,7<=$G8+$F8-1),$E8/$F8,0) -> 0 | O8: =IF(AND(8>=$G8,8<=$G8+$F8-1),$E8/$F8,0) -> 0 | P8: =IF(AND(9>=$G8,9<=$G8+$F8-1),$E8/$F8,0) -> 0 | Q8: =IF(AND(10>=$G8,10<=$G8+$F8-1),$E8/$F8,0) -> 0 | R8: =IF(AND(11>=$G8,11<=$G8+$F8-1),$E8/$F8,0) -> 0 | S8: =IF(AND(12>=$G8,12<=$G8+$F8-1),$E8/$F8,0) -> 0 | T8: =SUM(H8:S8) -> 7500 | U8: =$E8/$F8*MAX(0,MIN($F8,1-$G8)) -> 22500 | V8: =E8-T8-U8 -> 0
A9: Friis Cykler v/Brian Friis | B9: 45762 | C9: Faktura | D9: 37500 | E9: =D9/(1+Forudsætninger!$B$6) -> 30000 | F9: 12 | G9: =(YEAR(B9)-2026)*12+MONTH(B9) -> -8 | H9: =IF(AND(1>=$G9,1<=$G9+$F9-1),$E9/$F9,0) -> 2500 | I9: =IF(AND(2>=$G9,2<=$G9+$F9-1),$E9/$F9,0) -> 2500 | J9: =IF(AND(3>=$G9,3<=$G9+$F9-1),$E9/$F9,0) -> 2500 | K9: =IF(AND(4>=$G9,4<=$G9+$F9-1),$E9/$F9,0) -> 0 | L9: =IF(AND(5>=$G9,5<=$G9+$F9-1),$E9/$F9,0) -> 0 | M9: =IF(AND(6>=$G9,6<=$G9+$F9-1),$E9/$F9,0) -> 0 | N9: =IF(AND(7>=$G9,7<=$G9+$F9-1),$E9/$F9,0) -> 0 | O9: =IF(AND(8>=$G9,8<=$G9+$F9-1),$E9/$F9,0) -> 0 | P9: =IF(AND(9>=$G9,9<=$G9+$F9-1),$E9/$F9,0) -> 0 | Q9: =IF(AND(10>=$G9,10<=$G9+$F9-1),$E9/$F9,0) -> 0 | R9: =IF(AND(11>=$G9,11<=$G9+$F9-1),$E9/$F9,0) -> 0 | S9: =IF(AND(12>=$G9,12<=$G9+$F9-1),$E9/$F9,0) -> 0 | T9: =SUM(H9:S9) -> 7500 | U9: =$E9/$F9*MAX(0,MIN($F9,1-$G9)) -> 22500 | V9: =E9-T9-U9 -> 0
A10: CyberMinds ApS | B10: 45762 | C10: Faktura | D10: 37500 | E10: =D10/(1+Forudsætninger!$B$6) -> 30000 | F10: 12 | G10: =(YEAR(B10)-2026)*12+MONTH(B10) -> -8 | H10: =IF(AND(1>=$G10,1<=$G10+$F10-1),$E10/$F10,0) -> 2500 | I10: =IF(AND(2>=$G10,2<=$G10+$F10-1),$E10/$F10,0) -> 2500 | J10: =IF(AND(3>=$G10,3<=$G10+$F10-1),$E10/$F10,0) -> 2500 | K10: =IF(AND(4>=$G10,4<=$G10+$F10-1),$E10/$F10,0) -> 0 | L10: =IF(AND(5>=$G10,5<=$G10+$F10-1),$E10/$F10,0) -> 0 | M10: =IF(AND(6>=$G10,6<=$G10+$F10-1),$E10/$F10,0) -> 0 | N10: =IF(AND(7>=$G10,7<=$G10+$F10-1),$E10/$F10,0) -> 0 | O10: =IF(AND(8>=$G10,8<=$G10+$F10-1),$E10/$F10,0) -> 0 | P10: =IF(AND(9>=$G10,9<=$G10+$F10-1),$E10/$F10,0) -> 0 | Q10: =IF(AND(10>=$G10,10<=$G10+$F10-1),$E10/$F10,0) -> 0 | R10: =IF(AND(11>=$G10,11<=$G10+$F10-1),$E10/$F10,0) -> 0 | S10: =IF(AND(12>=$G10,12<=$G10+$F10-1),$E10/$F10,0) -> 0 | T10: =SUM(H10:S10) -> 7500 | U10: =$E10/$F10*MAX(0,MIN($F10,1-$G10)) -> 22500 | V10: =E10-T10-U10 -> 0
A11: Insurance Partners ApS (1. faktura) | B11: 45765 | C11: Faktura | D11: 18750 | E11: =D11/(1+Forudsætninger!$B$6) -> 15000 | F11: 12 | G11: =(YEAR(B11)-2026)*12+MONTH(B11) -> -8 | H11: =IF(AND(1>=$G11,1<=$G11+$F11-1),$E11/$F11,0) -> 1250 | I11: =IF(AND(2>=$G11,2<=$G11+$F11-1),$E11/$F11,0) -> 1250 | J11: =IF(AND(3>=$G11,3<=$G11+$F11-1),$E11/$F11,0) -> 1250 | K11: =IF(AND(4>=$G11,4<=$G11+$F11-1),$E11/$F11,0) -> 0 | L11: =IF(AND(5>=$G11,5<=$G11+$F11-1),$E11/$F11,0) -> 0 | M11: =IF(AND(6>=$G11,6<=$G11+$F11-1),$E11/$F11,0) -> 0 | N11: =IF(AND(7>=$G11,7<=$G11+$F11-1),$E11/$F11,0) -> 0 | O11: =IF(AND(8>=$G11,8<=$G11+$F11-1),$E11/$F11,0) -> 0 | P11: =IF(AND(9>=$G11,9<=$G11+$F11-1),$E11/$F11,0) -> 0 | Q11: =IF(AND(10>=$G11,10<=$G11+$F11-1),$E11/$F11,0) -> 0 | R11: =IF(AND(11>=$G11,11<=$G11+$F11-1),$E11/$F11,0) -> 0 | S11: =IF(AND(12>=$G11,12<=$G11+$F11-1),$E11/$F11,0) -> 0 | T11: =SUM(H11:S11) -> 3750 | U11: =$E11/$F11*MAX(0,MIN($F11,1-$G11)) -> 11250 | V11: =E11-T11-U11 -> 0
A12: Aqua Danmark A/S | B12: 45765 | C12: Faktura | D12: 37500 | E12: =D12/(1+Forudsætninger!$B$6) -> 30000 | F12: 12 | G12: =(YEAR(B12)-2026)*12+MONTH(B12) -> -8 | H12: =IF(AND(1>=$G12,1<=$G12+$F12-1),$E12/$F12,0) -> 2500 | I12: =IF(AND(2>=$G12,2<=$G12+$F12-1),$E12/$F12,0) -> 2500 | J12: =IF(AND(3>=$G12,3<=$G12+$F12-1),$E12/$F12,0) -> 2500 | K12: =IF(AND(4>=$G12,4<=$G12+$F12-1),$E12/$F12,0) -> 0 | L12: =IF(AND(5>=$G12,5<=$G12+$F12-1),$E12/$F12,0) -> 0 | M12: =IF(AND(6>=$G12,6<=$G12+$F12-1),$E12/$F12,0) -> 0 | N12: =IF(AND(7>=$G12,7<=$G12+$F12-1),$E12/$F12,0) -> 0 | O12: =IF(AND(8>=$G12,8<=$G12+$F12-1),$E12/$F12,0) -> 0 | P12: =IF(AND(9>=$G12,9<=$G12+$F12-1),$E12/$F12,0) -> 0 | Q12: =IF(AND(10>=$G12,10<=$G12+$F12-1),$E12/$F12,0) -> 0 | R12: =IF(AND(11>=$G12,11<=$G12+$F12-1),$E12/$F12,0) -> 0 | S12: =IF(AND(12>=$G12,12<=$G12+$F12-1),$E12/$F12,0) -> 0 | T12: =SUM(H12:S12) -> 7500 | U12: =$E12/$F12*MAX(0,MIN($F12,1-$G12)) -> 22500 | V12: =E12-T12-U12 -> 0
A13: KJ Auto v/Per Sørig Jensen | B13: 45770 | C13: Faktura | D13: 12500 | E13: =D13/(1+Forudsætninger!$B$6) -> 10000 | F13: 12 | G13: =(YEAR(B13)-2026)*12+MONTH(B13) -> -8 | H13: =IF(AND(1>=$G13,1<=$G13+$F13-1),$E13/$F13,0) -> 833.33333 | I13: =IF(AND(2>=$G13,2<=$G13+$F13-1),$E13/$F13,0) -> 833.33333 | J13: =IF(AND(3>=$G13,3<=$G13+$F13-1),$E13/$F13,0) -> 833.33333 | K13: =IF(AND(4>=$G13,4<=$G13+$F13-1),$E13/$F13,0) -> 0 | L13: =IF(AND(5>=$G13,5<=$G13+$F13-1),$E13/$F13,0) -> 0 | M13: =IF(AND(6>=$G13,6<=$G13+$F13-1),$E13/$F13,0) -> 0 | N13: =IF(AND(7>=$G13,7<=$G13+$F13-1),$E13/$F13,0) -> 0 | O13: =IF(AND(8>=$G13,8<=$G13+$F13-1),$E13/$F13,0) -> 0 | P13: =IF(AND(9>=$G13,9<=$G13+$F13-1),$E13/$F13,0) -> 0 | Q13: =IF(AND(10>=$G13,10<=$G13+$F13-1),$E13/$F13,0) -> 0 | R13: =IF(AND(11>=$G13,11<=$G13+$F13-1),$E13/$F13,0) -> 0 | S13: =IF(AND(12>=$G13,12<=$G13+$F13-1),$E13/$F13,0) -> 0 | T13: =SUM(H13:S13) -> 2500 | U13: =$E13/$F13*MAX(0,MIN($F13,1-$G13)) -> 7500 | V13: =E13-T13-U13 -> 0
A14: Box-cut.com ApS | B14: 45777 | C14: Faktura | D14: 37500 | E14: =D14/(1+Forudsætninger!$B$6) -> 30000 | F14: 12 | G14: =(YEAR(B14)-2026)*12+MONTH(B14) -> -8 | H14: =IF(AND(1>=$G14,1<=$G14+$F14-1),$E14/$F14,0) -> 2500 | I14: =IF(AND(2>=$G14,2<=$G14+$F14-1),$E14/$F14,0) -> 2500 | J14: =IF(AND(3>=$G14,3<=$G14+$F14-1),$E14/$F14,0) -> 2500 | K14: =IF(AND(4>=$G14,4<=$G14+$F14-1),$E14/$F14,0) -> 0 | L14: =IF(AND(5>=$G14,5<=$G14+$F14-1),$E14/$F14,0) -> 0 | M14: =IF(AND(6>=$G14,6<=$G14+$F14-1),$E14/$F14,0) -> 0 | N14: =IF(AND(7>=$G14,7<=$G14+$F14-1),$E14/$F14,0) -> 0 | O14: =IF(AND(8>=$G14,8<=$G14+$F14-1),$E14/$F14,0) -> 0 | P14: =IF(AND(9>=$G14,9<=$G14+$F14-1),$E14/$F14,0) -> 0 | Q14: =IF(AND(10>=$G14,10<=$G14+$F14-1),$E14/$F14,0) -> 0 | R14: =IF(AND(11>=$G14,11<=$G14+$F14-1),$E14/$F14,0) -> 0 | S14: =IF(AND(12>=$G14,12<=$G14+$F14-1),$E14/$F14,0) -> 0 | T14: =SUM(H14:S14) -> 7500 | U14: =$E14/$F14*MAX(0,MIN($F14,1-$G14)) -> 22500 | V14: =E14-T14-U14 -> 0
A15: Regnskabsvikar ApS | B15: 45782 | C15: Faktura | D15: 37500 | E15: =D15/(1+Forudsætninger!$B$6) -> 30000 | F15: 12 | G15: =(YEAR(B15)-2026)*12+MONTH(B15) -> -7 | H15: =IF(AND(1>=$G15,1<=$G15+$F15-1),$E15/$F15,0) -> 2500 | I15: =IF(AND(2>=$G15,2<=$G15+$F15-1),$E15/$F15,0) -> 2500 | J15: =IF(AND(3>=$G15,3<=$G15+$F15-1),$E15/$F15,0) -> 2500 | K15: =IF(AND(4>=$G15,4<=$G15+$F15-1),$E15/$F15,0) -> 2500 | L15: =IF(AND(5>=$G15,5<=$G15+$F15-1),$E15/$F15,0) -> 0 | M15: =IF(AND(6>=$G15,6<=$G15+$F15-1),$E15/$F15,0) -> 0 | N15: =IF(AND(7>=$G15,7<=$G15+$F15-1),$E15/$F15,0) -> 0 | O15: =IF(AND(8>=$G15,8<=$G15+$F15-1),$E15/$F15,0) -> 0 | P15: =IF(AND(9>=$G15,9<=$G15+$F15-1),$E15/$F15,0) -> 0 | Q15: =IF(AND(10>=$G15,10<=$G15+$F15-1),$E15/$F15,0) -> 0 | R15: =IF(AND(11>=$G15,11<=$G15+$F15-1),$E15/$F15,0) -> 0 | S15: =IF(AND(12>=$G15,12<=$G15+$F15-1),$E15/$F15,0) -> 0 | T15: =SUM(H15:S15) -> 10000 | U15: =$E15/$F15*MAX(0,MIN($F15,1-$G15)) -> 20000 | V15: =E15-T15-U15 -> 0
A16: Rock it Rosie ApS | B16: 45800 | C16: Faktura | D16: 50000 | E16: =D16/(1+Forudsætninger!$B$6) -> 40000 | F16: 12 | G16: =(YEAR(B16)-2026)*12+MONTH(B16) -> -7 | H16: =IF(AND(1>=$G16,1<=$G16+$F16-1),$E16/$F16,0) -> 3333.3333 | I16: =IF(AND(2>=$G16,2<=$G16+$F16-1),$E16/$F16,0) -> 3333.3333 | J16: =IF(AND(3>=$G16,3<=$G16+$F16-1),$E16/$F16,0) -> 3333.3333 | K16: =IF(AND(4>=$G16,4<=$G16+$F16-1),$E16/$F16,0) -> 3333.3333 | L16: =IF(AND(5>=$G16,5<=$G16+$F16-1),$E16/$F16,0) -> 0 | M16: =IF(AND(6>=$G16,6<=$G16+$F16-1),$E16/$F16,0) -> 0 | N16: =IF(AND(7>=$G16,7<=$G16+$F16-1),$E16/$F16,0) -> 0 | O16: =IF(AND(8>=$G16,8<=$G16+$F16-1),$E16/$F16,0) -> 0 | P16: =IF(AND(9>=$G16,9<=$G16+$F16-1),$E16/$F16,0) -> 0 | Q16: =IF(AND(10>=$G16,10<=$G16+$F16-1),$E16/$F16,0) -> 0 | R16: =IF(AND(11>=$G16,11<=$G16+$F16-1),$E16/$F16,0) -> 0 | S16: =IF(AND(12>=$G16,12<=$G16+$F16-1),$E16/$F16,0) -> 0 | T16: =SUM(H16:S16) -> 13333.333 | U16: =$E16/$F16*MAX(0,MIN($F16,1-$G16)) -> 26666.667 | V16: =E16-T16-U16 -> 0
A17: Warburg VVS & Kloak ekspres ApS | B17: 45824 | C17: Faktura | D17: 50000 | E17: =D17/(1+Forudsætninger!$B$6) -> 40000 | F17: 12 | G17: =(YEAR(B17)-2026)*12+MONTH(B17) -> -6 | H17: =IF(AND(1>=$G17,1<=$G17+$F17-1),$E17/$F17,0) -> 3333.3333 | I17: =IF(AND(2>=$G17,2<=$G17+$F17-1),$E17/$F17,0) -> 3333.3333 | J17: =IF(AND(3>=$G17,3<=$G17+$F17-1),$E17/$F17,0) -> 3333.3333 | K17: =IF(AND(4>=$G17,4<=$G17+$F17-1),$E17/$F17,0) -> 3333.3333 | L17: =IF(AND(5>=$G17,5<=$G17+$F17-1),$E17/$F17,0) -> 3333.3333 | M17: =IF(AND(6>=$G17,6<=$G17+$F17-1),$E17/$F17,0) -> 0 | N17: =IF(AND(7>=$G17,7<=$G17+$F17-1),$E17/$F17,0) -> 0 | O17: =IF(AND(8>=$G17,8<=$G17+$F17-1),$E17/$F17,0) -> 0 | P17: =IF(AND(9>=$G17,9<=$G17+$F17-1),$E17/$F17,0) -> 0 | Q17: =IF(AND(10>=$G17,10<=$G17+$F17-1),$E17/$F17,0) -> 0 | R17: =IF(AND(11>=$G17,11<=$G17+$F17-1),$E17/$F17,0) -> 0 | S17: =IF(AND(12>=$G17,12<=$G17+$F17-1),$E17/$F17,0) -> 0 | T17: =SUM(H17:S17) -> 16666.667 | U17: =$E17/$F17*MAX(0,MIN($F17,1-$G17)) -> 23333.333 | V17: =E17-T17-U17 -> 0
... A23: Stadio ApS (tidl. Wrizz ApS) | B23: 45961 | C23: Faktura | D23: 18750 | E23: =D23/(1+Forudsætninger!$B$6) -> 15000 | F23: 12 | G23: =(YEAR(B23)-2026)*12+MONTH(B23) -> -2 | H23: =IF(AND(1>=$G23,1<=$G23+$F23-1),$E23/$F23,0) -> 1250 | I23: =IF(AND(2>=$G23,2<=$G23+$F23-1),$E23/$F23,0) -> 1250 | J23: =IF(AND(3>=$G23,3<=$G23+$F23-1),$E23/$F23,0) -> 1250 | K23: =IF(AND(4>=$G23,4<=$G23+$F23-1),$E23/$F23,0) -> 1250 | L23: =IF(AND(5>=$G23,5<=$G23+$F23-1),$E23/$F23,0) -> 1250 | M23: =IF(AND(6>=$G23,6<=$G23+$F23-1),$E23/$F23,0) -> 1250 | N23: =IF(AND(7>=$G23,7<=$G23+$F23-1),$E23/$F23,0) -> 1250 | O23: =IF(AND(8>=$G23,8<=$G23+$F23-1),$E23/$F23,0) -> 1250 | P23: =IF(AND(9>=$G23,9<=$G23+$F23-1),$E23/$F23,0) -> 1250 | Q23: =IF(AND(10>=$G23,10<=$G23+$F23-1),$E23/$F23,0) -> 0 | R23: =IF(AND(11>=$G23,11<=$G23+$F23-1),$E23/$F23,0) -> 0 | S23: =IF(AND(12>=$G23,12<=$G23+$F23-1),$E23/$F23,0) -> 0 | T23: =SUM(H23:S23) -> 11250 | U23: =$E23/$F23*MAX(0,MIN($F23,1-$G23)) -> 3750 | V23: =E23-T23-U23 -> 0
A24: I alt — solgt i 2025 | D24: =SUM(D6:D23) -> 579312.5 | E24: =SUM(E6:E23) -> 463450 | H24: =SUM(H6:H23) -> 38620.833 | I24: =SUM(I6:I23) -> 38620.833 | J24: =SUM(J6:J23) -> 38620.833 | K24: =SUM(K6:K23) -> 20287.5 | L24: =SUM(L6:L23) -> 14454.167 | M24: =SUM(M6:M23) -> 11120.833 | N24: =SUM(N6:N23) -> 11120.833 | O24: =SUM(O6:O23) -> 7787.5 | ... V24: =SUM(V6:V23) -> 0
A26: SOLGT I 2026
A27: Line Bakke (2. faktura) | B27: 46042 | C27: Faktura | D27: 12500 | E27: =D27/(1+Forudsætninger!$B$6) -> 10000 | F27: 12 | G27: =(YEAR(B27)-2026)*12+MONTH(B27) -> 1 | H27: =IF(AND(1>=$G27,1<=$G27+$F27-1),$E27/$F27,0) -> 833.33333 | I27: =IF(AND(2>=$G27,2<=$G27+$F27-1),$E27/$F27,0) -> 833.33333 | J27: =IF(AND(3>=$G27,3<=$G27+$F27-1),$E27/$F27,0) -> 833.33333 | K27: =IF(AND(4>=$G27,4<=$G27+$F27-1),$E27/$F27,0) -> 833.33333 | L27: =IF(AND(5>=$G27,5<=$G27+$F27-1),$E27/$F27,0) -> 833.33333 | M27: =IF(AND(6>=$G27,6<=$G27+$F27-1),$E27/$F27,0) -> 833.33333 | N27: =IF(AND(7>=$G27,7<=$G27+$F27-1),$E27/$F27,0) -> 833.33333 | O27: =IF(AND(8>=$G27,8<=$G27+$F27-1),$E27/$F27,0) -> 833.33333 | P27: =IF(AND(9>=$G27,9<=$G27+$F27-1),$E27/$F27,0) -> 833.33333 | Q27: =IF(AND(10>=$G27,10<=$G27+$F27-1),$E27/$F27,0) -> 833.33333 | R27: =IF(AND(11>=$G27,11<=$G27+$F27-1),$E27/$F27,0) -> 833.33333 | S27: =IF(AND(12>=$G27,12<=$G27+$F27-1),$E27/$F27,0) -> 833.33333 | T27: =SUM(H27:S27) -> 10000 | U27: =$E27/$F27*MAX(0,MIN($F27,1-$G27)) -> 0 | V27: =E27-T27-U27 -> 0
A28: Rally Support ApS (P. H. Jacobsen) | B28: 46043 | C28: Stripe | D28: 50000 | E28: =D28/(1+Forudsætninger!$B$6) -> 40000 | F28: 12 | G28: =(YEAR(B28)-2026)*12+MONTH(B28) -> 1 | H28: =IF(AND(1>=$G28,1<=$G28+$F28-1),$E28/$F28,0) -> 3333.3333 | I28: =IF(AND(2>=$G28,2<=$G28+$F28-1),$E28/$F28,0) -> 3333.3333 | J28: =IF(AND(3>=$G28,3<=$G28+$F28-1),$E28/$F28,0) -> 3333.3333 | K28: =IF(AND(4>=$G28,4<=$G28+$F28-1),$E28/$F28,0) -> 3333.3333 | L28: =IF(AND(5>=$G28,5<=$G28+$F28-1),$E28/$F28,0) -> 3333.3333 | M28: =IF(AND(6>=$G28,6<=$G28+$F28-1),$E28/$F28,0) -> 3333.3333 | N28: =IF(AND(7>=$G28,7<=$G28+$F28-1),$E28/$F28,0) -> 3333.3333 | O28: =IF(AND(8>=$G28,8<=$G28+$F28-1),$E28/$F28,0) -> 3333.3333 | P28: =IF(AND(9>=$G28,9<=$G28+$F28-1),$E28/$F28,0) -> 3333.3333 | Q28: =IF(AND(10>=$G28,10<=$G28+$F28-1),$E28/$F28,0) -> 3333.3333 | R28: =IF(AND(11>=$G28,11<=$G28+$F28-1),$E28/$F28,0) -> 3333.3333 | S28: =IF(AND(12>=$G28,12<=$G28+$F28-1),$E28/$F28,0) -> 3333.3333 | T28: =SUM(H28:S28) -> 40000 | U28: =$E28/$F28*MAX(0,MIN($F28,1-$G28)) -> 0 | V28: =E28-T28-U28 -> 0
A29: Din økonomiafdeling Danmark ApS | B29: 46078 | C29: Faktura | D29: 50000 | E29: =D29/(1+Forudsætninger!$B$6) -> 40000 | F29: 12 | G29: =(YEAR(B29)-2026)*12+MONTH(B29) -> 2 | H29: =IF(AND(1>=$G29,1<=$G29+$F29-1),$E29/$F29,0) -> 0 | I29: =IF(AND(2>=$G29,2<=$G29+$F29-1),$E29/$F29,0) -> 3333.3333 | J29: =IF(AND(3>=$G29,3<=$G29+$F29-1),$E29/$F29,0) -> 3333.3333 | K29: =IF(AND(4>=$G29,4<=$G29+$F29-1),$E29/$F29,0) -> 3333.3333 | L29: =IF(AND(5>=$G29,5<=$G29+$F29-1),$E29/$F29,0) -> 3333.3333 | M29: =IF(AND(6>=$G29,6<=$G29+$F29-1),$E29/$F29,0) -> 3333.3333 | N29: =IF(AND(7>=$G29,7<=$G29+$F29-1),$E29/$F29,0) -> 3333.3333 | O29: =IF(AND(8>=$G29,8<=$G29+$F29-1),$E29/$F29,0) -> 3333.3333 | P29: =IF(AND(9>=$G29,9<=$G29+$F29-1),$E29/$F29,0) -> 3333.3333 | Q29: =IF(AND(10>=$G29,10<=$G29+$F29-1),$E29/$F29,0) -> 3333.3333 | R29: =IF(AND(11>=$G29,11<=$G29+$F29-1),$E29/$F29,0) -> 3333.3333 | S29: =IF(AND(12>=$G29,12<=$G29+$F29-1),$E29/$F29,0) -> 3333.3333 | T29: =SUM(H29:S29) -> 36666.667 | U29: =$E29/$F29*MAX(0,MIN($F29,1-$G29)) -> 0 | V29: =E29-T29-U29 -> 3333.3333
A30: Rezycl.com | B30: 46084 | C30: Faktura | D30: 43762.5 | E30: =D30/(1+Forudsætninger!$B$6) -> 35010 | F30: 12 | G30: =(YEAR(B30)-2026)*12+MONTH(B30) -> 3 | H30: =IF(AND(1>=$G30,1<=$G30+$F30-1),$E30/$F30,0) -> 0 | I30: =IF(AND(2>=$G30,2<=$G30+$F30-1),$E30/$F30,0) -> 0 | J30: =IF(AND(3>=$G30,3<=$G30+$F30-1),$E30/$F30,0) -> 2917.5 | K30: =IF(AND(4>=$G30,4<=$G30+$F30-1),$E30/$F30,0) -> 2917.5 | L30: =IF(AND(5>=$G30,5<=$G30+$F30-1),$E30/$F30,0) -> 2917.5 | M30: =IF(AND(6>=$G30,6<=$G30+$F30-1),$E30/$F30,0) -> 2917.5 | N30: =IF(AND(7>=$G30,7<=$G30+$F30-1),$E30/$F30,0) -> 2917.5 | O30: =IF(AND(8>=$G30,8<=$G30+$F30-1),$E30/$F30,0) -> 2917.5 | P30: =IF(AND(9>=$G30,9<=$G30+$F30-1),$E30/$F30,0) -> 2917.5 | Q30: =IF(AND(10>=$G30,10<=$G30+$F30-1),$E30/$F30,0) -> 2917.5 | R30: =IF(AND(11>=$G30,11<=$G30+$F30-1),$E30/$F30,0) -> 2917.5 | S30: =IF(AND(12>=$G30,12<=$G30+$F30-1),$E30/$F30,0) -> 2917.5 | T30: =SUM(H30:S30) -> 29175 | U30: =$E30/$F30*MAX(0,MIN($F30,1-$G30)) -> 0 | V30: =E30-T30-U30 -> 5835
A31: Ole Holdgaard | B31: 46153 | C31: Stripe | D31: 62500 | E31: =D31/(1+Forudsætninger!$B$6) -> 50000 | F31: 12 | G31: =(YEAR(B31)-2026)*12+MONTH(B31) -> 5 | H31: =IF(AND(1>=$G31,1<=$G31+$F31-1),$E31/$F31,0) -> 0 | I31: =IF(AND(2>=$G31,2<=$G31+$F31-1),$E31/$F31,0) -> 0 | J31: =IF(AND(3>=$G31,3<=$G31+$F31-1),$E31/$F31,0) -> 0 | K31: =IF(AND(4>=$G31,4<=$G31+$F31-1),$E31/$F31,0) -> 0 | L31: =IF(AND(5>=$G31,5<=$G31+$F31-1),$E31/$F31,0) -> 4166.6667 | M31: =IF(AND(6>=$G31,6<=$G31+$F31-1),$E31/$F31,0) -> 4166.6667 | N31: =IF(AND(7>=$G31,7<=$G31+$F31-1),$E31/$F31,0) -> 4166.6667 | O31: =IF(AND(8>=$G31,8<=$G31+$F31-1),$E31/$F31,0) -> 4166.6667 | P31: =IF(AND(9>=$G31,9<=$G31+$F31-1),$E31/$F31,0) -> 4166.6667 | Q31: =IF(AND(10>=$G31,10<=$G31+$F31-1),$E31/$F31,0) -> 4166.6667 | R31: =IF(AND(11>=$G31,11<=$G31+$F31-1),$E31/$F31,0) -> 4166.6667 | S31: =IF(AND(12>=$G31,12<=$G31+$F31-1),$E31/$F31,0) -> 4166.6667 | T31: =SUM(H31:S31) -> 33333.333 | U31: =$E31/$F31*MAX(0,MIN($F31,1-$G31)) -> 0 | V31: =E31-T31-U31 -> 16666.667
A32: Toft Administration ApS | B32: 46154 | C32: Faktura | D32: 62500 | E32: =D32/(1+Forudsætninger!$B$6) -> 50000 | F32: 12 | G32: =(YEAR(B32)-2026)*12+MONTH(B32) -> 5 | H32: =IF(AND(1>=$G32,1<=$G32+$F32-1),$E32/$F32,0) -> 0 | I32: =IF(AND(2>=$G32,2<=$G32+$F32-1),$E32/$F32,0) -> 0 | J32: =IF(AND(3>=$G32,3<=$G32+$F32-1),$E32/$F32,0) -> 0 | K32: =IF(AND(4>=$G32,4<=$G32+$F32-1),$E32/$F32,0) -> 0 | L32: =IF(AND(5>=$G32,5<=$G32+$F32-1),$E32/$F32,0) -> 4166.6667 | M32: =IF(AND(6>=$G32,6<=$G32+$F32-1),$E32/$F32,0) -> 4166.6667 | N32: =IF(AND(7>=$G32,7<=$G32+$F32-1),$E32/$F32,0) -> 4166.6667 | O32: =IF(AND(8>=$G32,8<=$G32+$F32-1),$E32/$F32,0) -> 4166.6667 | P32: =IF(AND(9>=$G32,9<=$G32+$F32-1),$E32/$F32,0) -> 4166.6667 | Q32: =IF(AND(10>=$G32,10<=$G32+$F32-1),$E32/$F32,0) -> 4166.6667 | R32: =IF(AND(11>=$G32,11<=$G32+$F32-1),$E32/$F32,0) -> 4166.6667 | S32: =IF(AND(12>=$G32,12<=$G32+$F32-1),$E32/$F32,0) -> 4166.6667 | T32: =SUM(H32:S32) -> 33333.333 | U32: =$E32/$F32*MAX(0,MIN($F32,1-$G32)) -> 0 | V32: =E32-T32-U32 -> 16666.667
A33: Line Almegaard ApS (3. faktura) | B33: 46170 | C33: Faktura | D33: 12500 | E33: =D33/(1+Forudsætninger!$B$6) -> 10000 | F33: 12 | G33: =(YEAR(B33)-2026)*12+MONTH(B33) -> 5 | H33: =IF(AND(1>=$G33,1<=$G33+$F33-1),$E33/$F33,0) -> 0 | I33: =IF(AND(2>=$G33,2<=$G33+$F33-1),$E33/$F33,0) -> 0 | J33: =IF(AND(3>=$G33,3<=$G33+$F33-1),$E33/$F33,0) -> 0 | K33: =IF(AND(4>=$G33,4<=$G33+$F33-1),$E33/$F33,0) -> 0 | L33: =IF(AND(5>=$G33,5<=$G33+$F33-1),$E33/$F33,0) -> 833.33333 | M33: =IF(AND(6>=$G33,6<=$G33+$F33-1),$E33/$F33,0) -> 833.33333 | N33: =IF(AND(7>=$G33,7<=$G33+$F33-1),$E33/$F33,0) -> 833.33333 | O33: =IF(AND(8>=$G33,8<=$G33+$F33-1),$E33/$F33,0) -> 833.33333 | P33: =IF(AND(9>=$G33,9<=$G33+$F33-1),$E33/$F33,0) -> 833.33333 | Q33: =IF(AND(10>=$G33,10<=$G33+$F33-1),$E33/$F33,0) -> 833.33333 | R33: =IF(AND(11>=$G33,11<=$G33+$F33-1),$E33/$F33,0) -> 833.33333 | S33: =IF(AND(12>=$G33,12<=$G33+$F33-1),$E33/$F33,0) -> 833.33333 | T33: =SUM(H33:S33) -> 6666.6667 | U33: =$E33/$F33*MAX(0,MIN($F33,1-$G33)) -> 0 | V33: =E33-T33-U33 -> 3333.3333
A34: Limo Group | B34: 46184 | C34: Faktura | D34: 62500 | E34: =D34/(1+Forudsætninger!$B$6) -> 50000 | F34: 12 | G34: =(YEAR(B34)-2026)*12+MONTH(B34) -> 6 | H34: =IF(AND(1>=$G34,1<=$G34+$F34-1),$E34/$F34,0) -> 0 | I34: =IF(AND(2>=$G34,2<=$G34+$F34-1),$E34/$F34,0) -> 0 | J34: =IF(AND(3>=$G34,3<=$G34+$F34-1),$E34/$F34,0) -> 0 | K34: =IF(AND(4>=$G34,4<=$G34+$F34-1),$E34/$F34,0) -> 0 | L34: =IF(AND(5>=$G34,5<=$G34+$F34-1),$E34/$F34,0) -> 0 | M34: =IF(AND(6>=$G34,6<=$G34+$F34-1),$E34/$F34,0) -> 4166.6667 | N34: =IF(AND(7>=$G34,7<=$G34+$F34-1),$E34/$F34,0) -> 4166.6667 | O34: =IF(AND(8>=$G34,8<=$G34+$F34-1),$E34/$F34,0) -> 4166.6667 | P34: =IF(AND(9>=$G34,9<=$G34+$F34-1),$E34/$F34,0) -> 4166.6667 | Q34: =IF(AND(10>=$G34,10<=$G34+$F34-1),$E34/$F34,0) -> 4166.6667 | R34: =IF(AND(11>=$G34,11<=$G34+$F34-1),$E34/$F34,0) -> 4166.6667 | S34: =IF(AND(12>=$G34,12<=$G34+$F34-1),$E34/$F34,0) -> 4166.6667 | T34: =SUM(H34:S34) -> 29166.667 | U34: =$E34/$F34*MAX(0,MIN($F34,1-$G34)) -> 0 | V34: =E34-T34-U34 -> 20833.333
A35: Warburg VVS (Christina Warburg) | B35: 46199 | C35: Stripe | D35: 18750 | E35: =D35/(1+Forudsætninger!$B$6) -> 15000 | F35: 12 | G35: =(YEAR(B35)-2026)*12+MONTH(B35) -> 6 | H35: =IF(AND(1>=$G35,1<=$G35+$F35-1),$E35/$F35,0) -> 0 | I35: =IF(AND(2>=$G35,2<=$G35+$F35-1),$E35/$F35,0) -> 0 | J35: =IF(AND(3>=$G35,3<=$G35+$F35-1),$E35/$F35,0) -> 0 | K35: =IF(AND(4>=$G35,4<=$G35+$F35-1),$E35/$F35,0) -> 0 | L35: =IF(AND(5>=$G35,5<=$G35+$F35-1),$E35/$F35,0) -> 0 | M35: =IF(AND(6>=$G35,6<=$G35+$F35-1),$E35/$F35,0) -> 1250 | N35: =IF(AND(7>=$G35,7<=$G35+$F35-1),$E35/$F35,0) -> 1250 | O35: =IF(AND(8>=$G35,8<=$G35+$F35-1),$E35/$F35,0) -> 1250 | P35: =IF(AND(9>=$G35,9<=$G35+$F35-1),$E35/$F35,0) -> 1250 | Q35: =IF(AND(10>=$G35,10<=$G35+$F35-1),$E35/$F35,0) -> 1250 | R35: =IF(AND(11>=$G35,11<=$G35+$F35-1),$E35/$F35,0) -> 1250 | S35: =IF(AND(12>=$G35,12<=$G35+$F35-1),$E35/$F35,0) -> 1250 | T35: =SUM(H35:S35) -> 8750 | U35: =$E35/$F35*MAX(0,MIN($F35,1-$G35)) -> 0 | V35: =E35-T35-U35 -> 6250
A36: Brilleværk ApS (fornyelse) | B36: 46254 | C36: Faktura | D36: 25000 | E36: =D36/(1+Forudsætninger!$B$6) -> 20000 | F36: 12 | G36: =(YEAR(B36)-2026)*12+MONTH(B36) -> 8 | H36: =IF(AND(1>=$G36,1<=$G36+$F36-1),$E36/$F36,0) -> 0 | I36: =IF(AND(2>=$G36,2<=$G36+$F36-1),$E36/$F36,0) -> 0 | J36: =IF(AND(3>=$G36,3<=$G36+$F36-1),$E36/$F36,0) -> 0 | K36: =IF(AND(4>=$G36,4<=$G36+$F36-1),$E36/$F36,0) -> 0 | L36: =IF(AND(5>=$G36,5<=$G36+$F36-1),$E36/$F36,0) -> 0 | M36: =IF(AND(6>=$G36,6<=$G36+$F36-1),$E36/$F36,0) -> 0 | N36: =IF(AND(7>=$G36,7<=$G36+$F36-1),$E36/$F36,0) -> 0 | O36: =IF(AND(8>=$G36,8<=$G36+$F36-1),$E36/$F36,0) -> 1666.6667 | P36: =IF(AND(9>=$G36,9<=$G36+$F36-1),$E36/$F36,0) -> 1666.6667 | Q36: =IF(AND(10>=$G36,10<=$G36+$F36-1),$E36/$F36,0) -> 1666.6667 | R36: =IF(AND(11>=$G36,11<=$G36+$F36-1),$E36/$F36,0) -> 1666.6667 | S36: =IF(AND(12>=$G36,12<=$G36+$F36-1),$E36/$F36,0) -> 1666.6667 | T36: =SUM(H36:S36) -> 8333.3333 | U36: =$E36/$F36*MAX(0,MIN($F36,1-$G36)) -> 0 | V36: =E36-T36-U36 -> 11666.667
A37: I alt — solgt i 2026 | D37: =SUM(D27:D36) -> 400012.5 | E37: =SUM(E27:E36) -> 320010 | H37: =SUM(H27:H36) -> 4166.6667 | I37: =SUM(I27:I36) -> 7500 | J37: =SUM(J27:J36) -> 10417.5 | K37: =SUM(K27:K36) -> 10417.5 | L37: =SUM(L27:L36) -> 19584.167 | M37: =SUM(M27:M36) -> 25000.833 | N37: =SUM(N27:N36) -> 25000.833 | O37: =SUM(O27:O36) -> 26667.5 | ... V37: =SUM(V27:V36) -> 84585
A39: BUDGETTERET NYSALG (sep–dec 2026)
A40: Nysalg Sep 2026 | B40: Sep 2026 | C40: Budget | D40: =E40*(1+Forudsætninger!$B$6) -> 62500 | E40: =Forudsætninger!$B$17*Forudsætninger!$B$18 -> 50000 | F40: 12 | G40: 9 | H40: =IF(AND(1>=$G40,1<=$G40+$F40-1),$E40/$F40,0) -> 0 | I40: =IF(AND(2>=$G40,2<=$G40+$F40-1),$E40/$F40,0) -> 0 | J40: =IF(AND(3>=$G40,3<=$G40+$F40-1),$E40/$F40,0) -> 0 | K40: =IF(AND(4>=$G40,4<=$G40+$F40-1),$E40/$F40,0) -> 0 | L40: =IF(AND(5>=$G40,5<=$G40+$F40-1),$E40/$F40,0) -> 0 | M40: =IF(AND(6>=$G40,6<=$G40+$F40-1),$E40/$F40,0) -> 0 | N40: =IF(AND(7>=$G40,7<=$G40+$F40-1),$E40/$F40,0) -> 0 | O40: =IF(AND(8>=$G40,8<=$G40+$F40-1),$E40/$F40,0) -> 0 | P40: =IF(AND(9>=$G40,9<=$G40+$F40-1),$E40/$F40,0) -> 4166.6667 | Q40: =IF(AND(10>=$G40,10<=$G40+$F40-1),$E40/$F40,0) -> 4166.6667 | R40: =IF(AND(11>=$G40,11<=$G40+$F40-1),$E40/$F40,0) -> 4166.6667 | S40: =IF(AND(12>=$G40,12<=$G40+$F40-1),$E40/$F40,0) -> 4166.6667 | T40: =SUM(H40:S40) -> 16666.667 | U40: =$E40/$F40*MAX(0,MIN($F40,1-$G40)) -> 0 | V40: =E40-T40-U40 -> 33333.333
A41: Nysalg Okt 2026 | B41: Okt 2026 | C41: Budget | D41: =E41*(1+Forudsætninger!$B$6) -> 62500 | E41: =Forudsætninger!$B$17*Forudsætninger!$B$18 -> 50000 | F41: 12 | G41: 10 | H41: =IF(AND(1>=$G41,1<=$G41+$F41-1),$E41/$F41,0) -> 0 | I41: =IF(AND(2>=$G41,2<=$G41+$F41-1),$E41/$F41,0) -> 0 | J41: =IF(AND(3>=$G41,3<=$G41+$F41-1),$E41/$F41,0) -> 0 | K41: =IF(AND(4>=$G41,4<=$G41+$F41-1),$E41/$F41,0) -> 0 | L41: =IF(AND(5>=$G41,5<=$G41+$F41-1),$E41/$F41,0) -> 0 | M41: =IF(AND(6>=$G41,6<=$G41+$F41-1),$E41/$F41,0) -> 0 | N41: =IF(AND(7>=$G41,7<=$G41+$F41-1),$E41/$F41,0) -> 0 | O41: =IF(AND(8>=$G41,8<=$G41+$F41-1),$E41/$F41,0) -> 0 | P41: =IF(AND(9>=$G41,9<=$G41+$F41-1),$E41/$F41,0) -> 0 | Q41: =IF(AND(10>=$G41,10<=$G41+$F41-1),$E41/$F41,0) -> 4166.6667 | R41: =IF(AND(11>=$G41,11<=$G41+$F41-1),$E41/$F41,0) -> 4166.6667 | S41: =IF(AND(12>=$G41,12<=$G41+$F41-1),$E41/$F41,0) -> 4166.6667 | T41: =SUM(H41:S41) -> 12500 | U41: =$E41/$F41*MAX(0,MIN($F41,1-$G41)) -> 0 | V41: =E41-T41-U41 -> 37500
A42: Nysalg Nov 2026 | B42: Nov 2026 | C42: Budget | D42: =E42*(1+Forudsætninger!$B$6) -> 62500 | E42: =Forudsætninger!$B$17*Forudsætninger!$B$18 -> 50000 | F42: 12 | G42: 11 | H42: =IF(AND(1>=$G42,1<=$G42+$F42-1),$E42/$F42,0) -> 0 | I42: =IF(AND(2>=$G42,2<=$G42+$F42-1),$E42/$F42,0) -> 0 | J42: =IF(AND(3>=$G42,3<=$G42+$F42-1),$E42/$F42,0) -> 0 | K42: =IF(AND(4>=$G42,4<=$G42+$F42-1),$E42/$F42,0) -> 0 | L42: =IF(AND(5>=$G42,5<=$G42+$F42-1),$E42/$F42,0) -> 0 | M42: =IF(AND(6>=$G42,6<=$G42+$F42-1),$E42/$F42,0) -> 0 | N42: =IF(AND(7>=$G42,7<=$G42+$F42-1),$E42/$F42,0) -> 0 | O42: =IF(AND(8>=$G42,8<=$G42+$F42-1),$E42/$F42,0) -> 0 | P42: =IF(AND(9>=$G42,9<=$G42+$F42-1),$E42/$F42,0) -> 0 | Q42: =IF(AND(10>=$G42,10<=$G42+$F42-1),$E42/$F42,0) -> 0 | R42: =IF(AND(11>=$G42,11<=$G42+$F42-1),$E42/$F42,0) -> 4166.6667 | S42: =IF(AND(12>=$G42,12<=$G42+$F42-1),$E42/$F42,0) -> 4166.6667 | T42: =SUM(H42:S42) -> 8333.3333 | U42: =$E42/$F42*MAX(0,MIN($F42,1-$G42)) -> 0 | V42: =E42-T42-U42 -> 41666.667
A43: Nysalg Dec 2026 | B43: Dec 2026 | C43: Budget | D43: =E43*(1+Forudsætninger!$B$6) -> 62500 | E43: =Forudsætninger!$B$17*Forudsætninger!$B$18 -> 50000 | F43: 12 | G43: 12 | H43: =IF(AND(1>=$G43,1<=$G43+$F43-1),$E43/$F43,0) -> 0 | I43: =IF(AND(2>=$G43,2<=$G43+$F43-1),$E43/$F43,0) -> 0 | J43: =IF(AND(3>=$G43,3<=$G43+$F43-1),$E43/$F43,0) -> 0 | K43: =IF(AND(4>=$G43,4<=$G43+$F43-1),$E43/$F43,0) -> 0 | L43: =IF(AND(5>=$G43,5<=$G43+$F43-1),$E43/$F43,0) -> 0 | M43: =IF(AND(6>=$G43,6<=$G43+$F43-1),$E43/$F43,0) -> 0 | N43: =IF(AND(7>=$G43,7<=$G43+$F43-1),$E43/$F43,0) -> 0 | O43: =IF(AND(8>=$G43,8<=$G43+$F43-1),$E43/$F43,0) -> 0 | P43: =IF(AND(9>=$G43,9<=$G43+$F43-1),$E43/$F43,0) -> 0 | Q43: =IF(AND(10>=$G43,10<=$G43+$F43-1),$E43/$F43,0) -> 0 | R43: =IF(AND(11>=$G43,11<=$G43+$F43-1),$E43/$F43,0) -> 0 | S43: =IF(AND(12>=$G43,12<=$G43+$F43-1),$E43/$F43,0) -> 4166.6667 | T43: =SUM(H43:S43) -> 4166.6667 | U43: =$E43/$F43*MAX(0,MIN($F43,1-$G43)) -> 0 | V43: =E43-T43-U43 -> 45833.333
A44: I alt — budgetteret nysalg | D44: =SUM(D40:D43) -> 250000 | E44: =SUM(E40:E43) -> 200000 | H44: =SUM(H40:H43) -> 0 | I44: =SUM(I40:I43) -> 0 | J44: =SUM(J40:J43) -> 0 | K44: =SUM(K40:K43) -> 0 | L44: =SUM(L40:L43) -> 0 | M44: =SUM(M40:M43) -> 0 | N44: =SUM(N40:N43) -> 0 | O44: =SUM(O40:O43) -> 0 | ... V44: =SUM(V40:V43) -> 158333.33
A46: PERIODISERET OMSÆTNING I ALT | D46: =D24+D37+D44 -> 1229325 | E46: =E24+E37+E44 -> 983460 | H46: =H24+H37+H44 -> 42787.5 | I46: =I24+I37+I44 -> 46120.833 | J46: =J24+J37+J44 -> 49038.333 | K46: =K24+K37+K44 -> 30705 | L46: =L24+L37+L44 -> 34038.333 | M46: =M24+M37+M44 -> 36121.667 | N46: =N24+N37+N44 -> 36121.667 | O46: =O24+O37+O44 -> 34455 | ... V46: =V24+V37+V44 -> 242918.33
A48: SÅDAN LÆSES ARKET
A49: Kolonne F (gul) er antal måneder forløbet løber over. Standard er 12. Ret den pr. linje, hvis en aftale løber kortere eller længere.
A50: Kolonne G er startmåned målt i forhold til januar 2026: april 2025 = -8, januar 2026 = 1, august 2026 = 8.
...

Sheet Omsætning
A1: Omsætning 2026
A2: Jan–jul = faktiske tal. Aug–dec = budget. Alle beløb i DKK ekskl. moms.
B3: FAKTISK | I3: BUDGET
B4: Jan | C4: Feb | D4: Mar | E4: Apr | F4: Maj | G4: Jun | H4: Jul | I4: Aug | J4: Sep | K4: Okt | L4: Nov | M4: Dec | N4: I alt 2026
A6: MEDLEMSBEVÆGELSE — LØBENDE ABONNEMENT
A7: Aktive medlemmer, primo | B7: 13 | C7: =B10 -> 13 | D7: =C10 -> 15 | E7: =D10 -> 17 | F7: =E10 -> 20 | G7: =F10 -> 20 | H7: =G10 -> 20 | I7: =H10 -> 18 | J7: =I10 -> 19 | ... M7: =L10 -> 22
A8: Tilgang, nye medlemmer | B8: 0 | C8: 3 | D8: 3 | E8: 3 | F8: 2 | G8: 1 | H8: 0 | I8: =Forudsætninger!$B$13 -> 2 | J8: =Forudsætninger!$B$13 -> 2 | K8: =Forudsætninger!$B$13 -> 2 | L8: =Forudsætninger!$B$13 -> 2 | M8: =Forudsætninger!$B$13 -> 2 | N8: =SUM(B8:M8) -> 22
A9: Afgang, opsigelser | B9: 0 | C9: 1 | D9: 1 | E9: 0 | F9: 2 | G9: 1 | H9: 2 | I9: =Forudsætninger!$B$14 -> 1 | J9: =Forudsætninger!$B$14 -> 1 | K9: =Forudsætninger!$B$14 -> 1 | L9: =Forudsætninger!$B$14 -> 1 | M9: =Forudsætninger!$B$14 -> 1 | N9: =SUM(B9:M9) -> 12
A10: Aktive medlemmer, ultimo | B10: =B7+B8-B9 -> 13 | C10: =C7+C8-C9 -> 15 | D10: =D7+D8-D9 -> 17 | E10: =E7+E8-E9 -> 20 | F10: =F7+F8-F9 -> 20 | G10: =G7+G8-G9 -> 20 | H10: =H7+H8-H9 -> 18 | I10: =I7+I8-I9 -> 19 | ... M10: =M7+M8-M9 -> 23 | N10: =M10 -> 23
A11: Faktisk jan–jul: primo januar 13 medlemmer. Tilgang = kunder med første Stripe-betaling i måneden, afgang beregnet som residual.
A12: Gennemsnit feb–jul: 2,0 nye og 1,2 opsigelser pr. måned. Det er grundlaget for aug–dec.
A14: MRR — MÅNEDLIG ABONNEMENTSOMSÆTNING
A15: MRR, primo | C15: =B18 -> 43030.56 | D15: =C18 -> 50030.56 | E15: =D18 -> 63000 | F15: =E18 -> 70875 | G15: =F18 -> 70437.5 | H15: =G18 -> 70437.5 | I15: =H18 -> 63437.5 | J15: =I18 -> 68663.194 | ... M15: =L18 -> 83854.167
A16: Tilgang nye (antal x listepris) | I16: =I8*Forudsætninger!$B$12 -> 8750 | J16: =J8*Forudsætninger!$B$12 -> 8750 | K16: =K8*Forudsætninger!$B$12 -> 8750 | L16: =L8*Forudsætninger!$B$12 -> 8750 | M16: =M8*Forudsætninger!$B$12 -> 8750
A17: Afgang opsigelser (antal x gns. pris) | I17: =IF(I7=0,0,I9*I15/I7) -> 3524.3056 | J17: =IF(J7=0,0,J9*J15/J7) -> 3613.8523 | K17: =IF(K7=0,0,K9*K15/K7) -> 3689.9671 | L17: =IF(L7=0,0,L9*L15/L7) -> 3755.2083 | M17: =IF(M7=0,0,M9*M15/M7) -> 3811.553
A18: MRR, ultimo | B18: 43030.56 | C18: 50030.56 | D18: 63000 | E18: 70875 | F18: 70437.5 | G18: 70437.5 | H18: 63437.5 | I18: =I15+I16-I17 -> 68663.194 | J18: =J15+J16-J17 -> 73799.342 | K18: =K15+K16-K17 -> 78859.375 | L18: =L15+L16-L17 -> 83854.167 | M18: =M15+M16-M17 -> 88792.614 | N18: =M18 -> 88792.614
A20: OMSÆTNING
A21: Løbende medlemsabonnement | B21: =B18 -> 43030.56 | C21: =C18 -> 50030.56 | D21: =D18 -> 63000 | E21: =E18 -> 70875 | F21: =F18 -> 70437.5 | G21: =G18 -> 70437.5 | H21: =H18 -> 63437.5 | I21: =I18 -> 68663.194 | ... M21: =M18 -> 88792.614 | N21: =SUM(B21:M21) -> 825217.31
A22: Periodiseret fuldbetaling — solgt i 2025 | B22: =Periodisering!H24 -> 38620.833 | C22: =Periodisering!I24 -> 38620.833 | D22: =Periodisering!J24 -> 38620.833 | E22: =Periodisering!K24 -> 20287.5 | F22: =Periodisering!L24 -> 14454.167 | G22: =Periodisering!M24 -> 11120.833 | H22: =Periodisering!N24 -> 11120.833 | I22: =Periodisering!O24 -> 7787.5 | ... M22: =Periodisering!S24 -> 0 | N22: =SUM(B22:M22) -> 186466.67
A23: Periodiseret fuldbetaling — solgt i 2026 | B23: =Periodisering!H37 -> 4166.6667 | C23: =Periodisering!I37 -> 7500 | D23: =Periodisering!J37 -> 10417.5 | E23: =Periodisering!K37 -> 10417.5 | F23: =Periodisering!L37 -> 19584.167 | G23: =Periodisering!M37 -> 25000.833 | H23: =Periodisering!N37 -> 25000.833 | I23: =Periodisering!O37 -> 26667.5 | ... M23: =Periodisering!S37 -> 26667.5 | N23: =SUM(B23:M23) -> 235425
A24: Periodiseret fuldbetaling — budgetteret nysalg | B24: =Periodisering!H44 -> 0 | C24: =Periodisering!I44 -> 0 | D24: =Periodisering!J44 -> 0 | E24: =Periodisering!K44 -> 0 | F24: =Periodisering!L44 -> 0 | G24: =Periodisering!M44 -> 0 | H24: =Periodisering!N44 -> 0 | I24: =Periodisering!O44 -> 0 | ... M24: =Periodisering!S44 -> 16666.667 | N24: =SUM(B24:M24) -> 41666.667
A25: Konsulent & øvrig omsætning | B25: 0 | C25: 0 | D25: 0 | E25: 2525 | F25: 12772.24 | G25: 1000 | H25: 0 | I25: =Forudsætninger!$B$22 -> 2500 | J25: =Forudsætninger!$B$22 -> 2500 | K25: =Forudsætninger!$B$22 -> 2500 | L25: =Forudsætninger!$B$22 -> 2500 | M25: =Forudsætninger!$B$22 -> 2500 | N25: =SUM(B25:M25) -> 28797.24
A26: Omsætning i alt | B26: =SUM(B21:B25) -> 85818.06 | C26: =SUM(C21:C25) -> 96151.393 | D26: =SUM(D21:D25) -> 112038.33 | E26: =SUM(E21:E25) -> 104105 | F26: =SUM(F21:F25) -> 117248.07 | G26: =SUM(G21:G25) -> 107559.17 | H26: =SUM(H21:H25) -> 99559.167 | I26: =SUM(I21:I25) -> 105618.19 | ... M26: =SUM(M21:M25) -> 134626.78 | N26: =SUM(B26:M26) -> 1317572.9
A28: Konsulent & øvrig omsætning jan–jul (efter fakturadato): Rn Group 2.125 (apr.), Rn Group 6.000 + Vinhuset 6.772 (maj), 1.000 fra Stripe (jun.).
A29: Line Bakkes faktura af 20.01.2026 er flyttet til Periodisering, da den ser ud til at være en rate på et medlemsforløb.

Sheet Omkostninger
A1: Omkostninger 2026
A2: Jan–jul = faktiske tal. Aug–dec = budget styret af kolonne Q. Alle beløb i DKK ekskl. moms.
B3: FAKTISK | I3: BUDGET
B4: Jan | C4: Feb | D4: Mar | E4: Apr | F4: Maj | G4: Jun | H4: Jul | I4: Aug | J4: Sep | K4: Okt | L4: Nov | M4: Dec | N4: I alt 2026 | P4: Gns./md jan–jul | Q4: Budget/md aug–dec | R4: Kilde / bemærkning
A5: DIREKTE OMKOSTNINGER — RÅDGIVNING & LEVERANCE
A6: Mola Partners ApS | B6: 15000 | C6: 45000 | D6: 35000 | E6: 0 | F6: 0 | G6: 68640 | H6: 0 | I6: =$Q6 -> 23377 | J6: =$Q6 -> 23377 | K6: =$Q6 -> 23377 | L6: =$Q6 -> 23377 | M6: =$Q6 -> 23377 | N6: =SUM(B6:M6) -> 280525 | P6: =AVERAGE(B6:H6) -> 23377.143 | Q6: 23377 | R6: Bank. Største enkeltpost. Ingen betalinger i juli og august.
A7: Sentury ApS | B7: 17100 | C7: 12300 | D7: 13875 | E7: 17700 | F7: 9975 | G7: 0 | H7: 16275 | I7: =$Q7 -> 12461 | J7: =$Q7 -> 12461 | K7: =$Q7 -> 12461 | L7: =$Q7 -> 12461 | M7: =$Q7 -> 12461 | N7: =SUM(B7:M7) -> 149530 | P7: =AVERAGE(B7:H7) -> 12460.714 | Q7: 12461 | R7: Bank.
A8: Oaksmond ApS | B8: 0 | C8: 0 | D8: 12000 | E8: 3500 | F8: 0 | G8: 3500 | H8: 3500 | I8: =$Q8 -> 3500 | J8: =$Q8 -> 3500 | K8: =$Q8 -> 3500 | L8: =$Q8 -> 3500 | M8: =$Q8 -> 3500 | N8: =SUM(B8:M8) -> 40000 | P8: =AVERAGE(B8:H8) -> 3214.2857 | Q8: 3500 | R8: Bank. Fast 4.375 inkl. moms/md fra april + 15.000 i marts.
A9: Mola Invest ApS | B9: 0 | C9: 2500 | D9: 3705.64 | E9: 5050 | F9: 2550 | G9: 2550 | H9: 2550 | I9: =$Q9 -> 2550 | J9: =$Q9 -> 2550 | K9: =$Q9 -> 2550 | L9: =$Q9 -> 2550 | M9: =$Q9 -> 2550 | N9: =SUM(B9:M9) -> 31655.64 | P9: =AVERAGE(B9:H9) -> 2700.8057 | Q9: 2550 | R9: Bank. Fast 3.187,50 inkl. moms/md.
A10: Rn Group ApS | B10: 0 | C10: 0 | D10: 700 | E10: 0 | F10: 0 | G10: 0 | H10: 0 | I10: =$Q10 -> 0 | J10: =$Q10 -> 0 | K10: =$Q10 -> 0 | L10: =$Q10 -> 0 | M10: =$Q10 -> 0 | N10: =SUM(B10:M10) -> 700 | P10: =AVERAGE(B10:H10) -> 100 | Q10: 0 | R10: Bank. Engangspost. Rn Group er også kunde — skal der nettes?
A11: Direkte Omkostninger i alt | B11: =SUM(B6:B10) -> 32100 | C11: =SUM(C6:C10) -> 59800 | D11: =SUM(D6:D10) -> 65280.64 | E11: =SUM(E6:E10) -> 26250 | F11: =SUM(F6:F10) -> 12525 | G11: =SUM(G6:G10) -> 74690 | H11: =SUM(H6:H10) -> 22325 | I11: =SUM(I6:I10) -> 41888 | ... N11: =SUM(N6:N10) -> 502410.64 | Q11: =SUM(Q6:Q10) -> 41888
A13: SALG & MARKETING
A14: Meta Ads | B14: 0 | C14: 4760.45 | D14: 120.26 | E14: 5749.5 | F14: 19088.8 | G14: 14402.8 | H14: 1593.04 | I14: =$Q14 -> 6531 | J14: =$Q14 -> 6531 | K14: =$Q14 -> 6531 | L14: =$Q14 -> 6531 | M14: =$Q14 -> 6531 | N14: =SUM(B14:M14) -> 78369.85 | P14: =AVERAGE(B14:H14) -> 6530.6929 | Q14: 6531 | R14: Pleo. Meget svingende. Aug. til 22.08: 4.039 kr.
A15: E-mail marketing (Klaviyo) | B15: 421.92 | C15: 414.88 | D15: 425.85 | E15: 421.02 | F15: 418.14 | G15: 425.36 | H15: 430.38 | I15: =$Q15 -> 423 | J15: =$Q15 -> 423 | K15: =$Q15 -> 423 | L15: =$Q15 -> 423 | M15: =$Q15 -> 423 | N15: =SUM(B15:M15) -> 5072.55 | P15: =AVERAGE(B15:H15) -> 422.50714 | Q15: 423 | R15: Pleo.
A16: Salg & Marketing i alt | B16: =SUM(B14:B15) -> 421.92 | C16: =SUM(C14:C15) -> 5175.33 | D16: =SUM(D14:D15) -> 546.11 | E16: =SUM(E14:E15) -> 6170.52 | F16: =SUM(F14:F15) -> 19506.94 | G16: =SUM(G14:G15) -> 14828.16 | H16: =SUM(H14:H15) -> 2023.42 | I16: =SUM(I14:I15) -> 6954 | ... N16: =SUM(N14:N15) -> 83442.4 | Q16: =SUM(Q14:Q15) -> 6954
A18: SOFTWARE & IT
A19: Software — verden (Lovable, Anthropic, Cloudflare m.fl.) | B19: 4120.33 | C19: 4388.63 | D19: 6876.74 | E19: 1564.31 | F19: 1687.75 | G19: 4754.36 | H19: 1868.14 | I19: =$Q19 -> 3609 | J19: =$Q19 -> 3609 | K19: =$Q19 -> 3609 | L19: =$Q19 -> 3609 | M19: =$Q19 -> 3609 | N19: =SUM(B19:M19) -> 43305.26 | P19: =AVERAGE(B19:H19) -> 3608.6086 | Q19: 3609 | R19: Pleo.
A20: Software — EU (monday.com, Google, Slack, Stape) | B20: 2040.07 | C20: 933.11 | D20: 763 | E20: 4230.48 | F20: 301.01 | G20: 301.06 | H20: 301.1 | I20: =$Q20 -> 1267 | J20: =$Q20 -> 1267 | K20: =$Q20 -> 1267 | L20: =$Q20 -> 1267 | M20: =$Q20 -> 1267 | N20: =SUM(B20:M20) -> 15204.83 | P20: =AVERAGE(B20:H20) -> 1267.1186 | Q20: 1267 | R20: Pleo.
A21: Software — DK (e-conomic, Cookie Information, IEX) | B21: 2068.11 | C21: 2417.82 | D21: 121.11 | E21: 2068.11 | F21: 0 | G21: 0 | H21: 1947 | I21: =$Q21 -> 1232 | J21: =$Q21 -> 1232 | K21: =$Q21 -> 1232 | L21: =$Q21 -> 1232 | M21: =$Q21 -> 1232 | N21: =SUM(B21:M21) -> 14782.15 | P21: =AVERAGE(B21:H21) -> 1231.7357 | Q21: 1232 | R21: Pleo.
A22: Visma e-conomic (faktura) | B22: 1947 | C22: 0 | D22: 0 | E22: 0 | F22: 0 | G22: 0 | H22: 0 | I22: =$Q22 -> 0 | J22: =$Q22 -> 0 | K22: =$Q22 -> 0 | L22: =$Q22 -> 0 | M22: =$Q22 -> 0 | N22: =SUM(B22:M22) -> 1947 | P22: =AVERAGE(B22:H22) -> 278.14286 | Q22: 0 | R22: Corpay-faktura 12.01.2026, ikke fundet på bankkontoen.
A23: Software & It i alt | B23: =SUM(B19:B22) -> 10175.51 | C23: =SUM(C19:C22) -> 7739.56 | D23: =SUM(D19:D22) -> 7760.85 | E23: =SUM(E19:E22) -> 7862.9 | F23: =SUM(F19:F22) -> 1988.76 | G23: =SUM(G19:G22) -> 5055.42 | H23: =SUM(H19:H22) -> 4116.24 | I23: =SUM(I19:I22) -> 6108 | ... N23: =SUM(N19:N22) -> 75239.24 | Q23: =SUM(Q19:Q22) -> 6108
A25: PERSONALE
A26: Løn inkl. A-skat og AM-bidrag | B26: 19901 | C26: 29901 | D26: 25354.89 | E26: 24901 | F26: 19901 | G26: 36450.21 | H26: 34901 | I26: =$Q26 -> 27330 | J26: =$Q26 -> 27330 | K26: =$Q26 -> 27330 | L26: =$Q26 -> 27330 | M26: =$Q26 -> 27330 | N26: =SUM(B26:M26) -> 327960.1 | P26: =AVERAGE(B26:H26) -> 27330.014 | Q26: 27330 | R26: Bank: nettoløn + A-skat/AM afregnet den 10. i efterfølgende måned.
A27: &Peopl ApS | B27: 6535.8 | C27: 0 | D27: 0 | E27: 14015.43 | F27: 0 | G27: 0 | H27: 6632.74 | I27: =$Q27 -> 3883 | J27: =$Q27 -> 3883 | K27: =$Q27 -> 3883 | L27: =$Q27 -> 3883 | M27: =$Q27 -> 3883 | N27: =SUM(B27:M27) -> 46598.97 | P27: =AVERAGE(B27:H27) -> 3883.4243 | Q27: 3883 | R27: Bank. Uregelmæssig. &peopl er også kunde (faktura sep. 2025).
A28: Lønsystem (Paychex) | B28: 0 | C28: 0 | D28: 25 | E28: 25 | F28: 25 | G28: 25 | H28: 25 | I28: =$Q28 -> 25 | J28: =$Q28 -> 25 | K28: =$Q28 -> 25 | L28: =$Q28 -> 25 | M28: =$Q28 -> 25 | N28: =SUM(B28:M28) -> 250 | P28: =AVERAGE(B28:H28) -> 17.857143 | Q28: 25 | R28: Bank.
A29: Personale i alt | B29: =SUM(B26:B28) -> 26436.8 | C29: =SUM(C26:C28) -> 29901 | D29: =SUM(D26:D28) -> 25379.89 | E29: =SUM(E26:E28) -> 38941.43 | F29: =SUM(F26:F28) -> 19926 | G29: =SUM(G26:G28) -> 36475.21 | H29: =SUM(H26:H28) -> 41558.74 | I29: =SUM(I26:I28) -> 31238 | ... N29: =SUM(N26:N28) -> 374809.07 | Q29: =SUM(Q26:Q28) -> 31238
A31: LOKALE & ADMINISTRATION
A32: Floor1 I/S — kontorleje | B32: 1493.5 | C32: 1493.5 | D32: 1493.5 | E32: 1493.5 | F32: 1493.5 | G32: 1493.5 | H32: 1493.5 | I32: =$Q32 -> 1493 | J32: =$Q32 -> 1493 | K32: =$Q32 -> 1493 | L32: =$Q32 -> 1493 | M32: =$Q32 -> 1493 | N32: =SUM(B32:M32) -> 17919.5 | P32: =AVERAGE(B32:H32) -> 1493.5 | Q32: 1493 | R32: Bank. Fast 1.866,88 inkl. moms/md.
A33: Rytterkasernen 21 ApS | B33: 0 | C33: 0 | D33: 13972 | E33: 0 | F33: 0 | G33: 0 | H33: 0 | I33: =$Q33 -> 0 | J33: =$Q33 -> 0 | K33: =$Q33 -> 0 | L33: =$Q33 -> 0 | M33: =$Q33 -> 0 | N33: =SUM(B33:M33) -> 13972 | P33: =AVERAGE(B33:H33) -> 1996 | Q33: 0 | R33: Bank. Engangspost marts. Gentager den sig?
A34: BDO — revisor | B34: 0 | C34: 0 | D34: 7825 | E34: 0 | F34: 0 | G34: 0 | H34: 0 | I34: =$Q34 -> 0 | J34: =$Q34 -> 0 | K34: =$Q34 -> 0 | L34: =$Q34 -> 0 | M34: =$Q34 -> 0 | N34: =SUM(B34:M34) -> 7825 | P34: =AVERAGE(B34:H34) -> 1117.8571 | Q34: 0 | R34: Bank. Årsregnskab. Kommer der flere honorarer i 2026?
A35: Corpay One | B35: 0 | C35: 0 | D35: 0 | E35: 59.5 | F35: 0 | G35: 59.5 | H35: 0 | I35: =$Q35 -> 34 | J35: =$Q35 -> 34 | K35: =$Q35 -> 34 | L35: =$Q35 -> 34 | M35: =$Q35 -> 34 | N35: =SUM(B35:M35) -> 289 | P35: =AVERAGE(B35:H35) -> 17 | Q35: 34 | R35: Bank.
A36: Samlet Betaling | B36: 0 | C36: 1179.8 | D36: 0 | E36: 0 | F36: 0 | G36: 0 | H36: 0 | I36: =$Q36 -> 0 | J36: =$Q36 -> 0 | K36: =$Q36 -> 0 | L36: =$Q36 -> 0 | M36: =$Q36 -> 0 | N36: =SUM(B36:M36) -> 1179.8 | P36: =AVERAGE(B36:H36) -> 168.54286 | Q36: 0 | R36: Bank. Uidentificeret. Aug.: 3.154,42 inkl. moms.
A37: Diverse / udlæg | B37: 0 | C37: 0 | D37: 0 | E37: 0 | F37: 1646.42 | G37: 0 | H37: 0 | I37: =$Q37 -> 400 | J37: =$Q37 -> 400 | K37: =$Q37 -> 400 | L37: =$Q37 -> 400 | M37: =$Q37 -> 400 | N37: =SUM(B37:M37) -> 3646.42 | P37: =AVERAGE(B37:H37) -> 235.20286 | Q37: 400 | R37: Bank: Bs-betaling 2.058 (maj) + Pleo mad 500 (apr.) + udlæg Jonas 1.606 (aug.).
A38: Bankgebyrer | B38: 482.5 | C38: 108.75 | D38: 113.75 | E38: 487.5 | F38: 108.75 | G38: 112.5 | H38: 110 | I38: =$Q38 -> 150 | J38: =$Q38 -> 150 | K38: =$Q38 -> 150 | L38: =$Q38 -> 150 | M38: =$Q38 -> 150 | N38: =SUM(B38:M38) -> 2273.75 | P38: =AVERAGE(B38:H38) -> 217.67857 | Q38: 150 | R38: Bank.
A39: Stripe-gebyrer | B39: 2498.74 | C39: 1510.56 | D39: 1887.58 | E39: 2103.74 | F39: 3598.58 | G39: 2575.94 | H39: 1883.16 | I39: =$Q39 -> 2294 | J39: =$Q39 -> 2294 | K39: =$Q39 -> 2294 | L39: =$Q39 -> 2294 | M39: =$Q39 -> 2294 | N39: =SUM(B39:M39) -> 27528.3 | P39: =AVERAGE(B39:H39) -> 2294.0429 | Q39: 2294 | R39: Stripe. Ca. 2,39 % af Stripe-omsætningen.
A40: Lokale & Administration i alt | B40: =SUM(B32:B39) -> 4474.74 | C40: =SUM(C32:C39) -> 4292.61 | D40: =SUM(D32:D39) -> 25291.83 | E40: =SUM(E32:E39) -> 4144.24 | F40: =SUM(F32:F39) -> 6847.25 | G40: =SUM(G32:G39) -> 4241.44 | H40: =SUM(H32:H39) -> 3486.66 | I40: =SUM(I32:I39) -> 4371 | ... N40: =SUM(N32:N39) -> 74633.77 | Q40: =SUM(Q32:Q39) -> 4371
A42: OMKOSTNINGER I ALT | B42: =B11+B16+B23+B29+B40 -> 73608.97 | C42: =C11+C16+C23+C29+C40 -> 106908.5 | D42: =D11+D16+D23+D29+D40 -> 124259.32 | E42: =E11+E16+E23+E29+E40 -> 83369.09 | F42: =F11+F16+F23+F29+F40 -> 60793.95 | G42: =G11+G16+G23+G29+G40 -> 135290.23 | H42: =H11+H16+H23+H29+H40 -> 73510.06 | I42: =I11+I16+I23+I29+I40 -> 90559 | ... N42: =N11+N16+N23+N29+N40 -> 1110535.1 | Q42: =Q11+Q16+Q23+Q29+Q40 -> 90559
A44: Gule celler i kolonne Q styrer budgettet for aug–dec. Kolonne P viser det faktiske månedsgennemsnit jan–jul som pejlemærke.
A45: Fakturaer fra danske leverandører er omregnet fra inkl. til ekskl. moms (÷1,25). Pleo-tal er nettobeløb fra Pleo-eksporten.
