Workbook

Sheet Opsætning2025
A1: Opsætning
A3: Generelt
A4: Virksomhed | B4: Topix.dk ApS
A5: Valuta | B5: DKK
A6: Budgetår | B6: 2025
A7: Momssats | B7: 0.25 | C7: =B7+1 -> 1.25
A8: Lønrelaterede omkostninger (feriepenge + div.) | B8: 0.16
A10: Måneder | B10: januar-25 | C10: februar-25 | D10: marts-25 | E10: april-25 | F10: maj-25 | G10: juni-25 | H10: juli-25 | I10: august-25 | J10: september-25 | K10: oktober-25 | L10: november-25 | M10: december-25 | N10: Total:
A11: Dage i måned | B11: =DAY(EOMONTH(B$10,0)) -> 31 | C11: =DAY(EOMONTH(C$10,0)) -> 28 | D11: =DAY(EOMONTH(D$10,0)) -> 31 | E11: =DAY(EOMONTH(E$10,0)) -> 30 | F11: =DAY(EOMONTH(F$10,0)) -> 31 | G11: =DAY(EOMONTH(G$10,0)) -> 30 | H11: =DAY(EOMONTH(H$10,0)) -> 31 | I11: =DAY(EOMONTH(I$10,0)) -> 31 | ... M11: =DAY(EOMONTH(M$10,0)) -> 31
A12: Omsætning
A13: Topix medlemmer | B13: 0 | C13: =$B$50/10*0 -> 0 | D13: =$B$50/10*0.5 -> 2 | E13: =$B$50/10 -> 4 | F13: 4 | G13: 4 | H13: 4 | I13: 20 | J13: 20 | K13: 20 | L13: 20 | M13: 20 | N13: =SUM(B13:M13) -> 118
A14: Boardroom medlemmer | E14: 8 | F14: 7 | G14: 2 | H14: 0 | I14: 6 | J14: 6 | K14: 5 | L14: 3 | M14: 3 | N14: =SUM(B14:M14) -> 40
A15: Topix pris pr medlem | B15: 5000 | C15: 5000 | D15: 5000 | E15: 5000 | F15: 5000 | G15: 5000 | H15: 5000 | I15: 5000 | J15: 5000 | K15: 5000 | L15: 5000 | M15: 5000
A16: Boardroom pris pr medlem | B16: =SUM($C$52) -> 0 | C16: =SUM($C$52) -> 0 | D16: =SUM($C$52) -> 0 | E16: 30000 | F16: 40000 | G16: 40000 | H16: 40000 | I16: 40000 | J16: 40000 | K16: 40000 | L16: 40000 | M16: 40000
A18: Marketing
A19: Marketingspend | B19: 0 | C19: 15000 | D19: 2313 | E19: 0 | F19: 15000 | G19: 10000 | H19: 10000 | I19: 15000 | J19: 15000 | K19: 15000 | L19: 15000 | M19: 15000 | N19: =SUM(B19:M19) -> 127313
A20: Spend Management | B20: 0 | C20: 6000 | E20: 0 | G20: 0 | H20: 0 | I20: 0 | J20: 6000 | K20: 6000 | L20: 6000 | M20: 6000 | N20: =SUM(B20:M20) -> 30000
A22: Logistik & Fragt
A23: Gns. fragtpris per D2C ordre | B23: 0 | C23: 0 | D23: 0 | E23: 0 | F23: 0 | G23: 0 | H23: 0 | I23: 0 | J23: 0 | K23: 0 | L23: 0 | M23: 0
A24: Gns. emballagepris per D2C ordre (inkl pluk/pak) | B24: 0 | C24: 0 | D24: 0 | E24: 0 | F24: 0 | G24: 0 | H24: 0 | I24: 0 | J24: 0 | K24: 0 | L24: 0 | M24: 0
A25: Returgebyr ved uafhentet pakke | B25: 0 | C25: 0 | D25: 0 | E25: 0 | F25: 0 | G25: 0 | H25: 0 | I25: 0 | J25: 0 | K25: 0 | L25: 0 | M25: 0
A26: Returprocent | B26: 0 | C26: 0 | D26: 0 | E26: 0 | F26: 0 | G26: 0 | H26: 0 | I26: 0 | J26: 0 | K26: 0 | L26: 0 | M26: 0
A27: B2B Fragt | B27: 0 | C27: 0 | D27: 0 | E27: 0 | F27: 0 | G27: 0 | H27: 0 | I27: 0 | J27: 0 | K27: 0 | L27: 0 | M27: 0
A29: Betalingshåndtering
A30: Abonnement | B30: 0 | C30: 0 | D30: 0 | E30: 0 | F30: 0 | G30: 0 | H30: 0 | I30: 0 | J30: 0 | K30: 0 | L30: 0 | M30: 0
A31: Betalingsgebyr (%) | B31: =B34 -> 0.035 | C31: =B34 -> 0.035 | D31: =B34 -> 0.035 | E31: =B34 -> 0.035 | F31: =B34 -> 0.035 | G31: =B34 -> 0.035 | H31: =B34 -> 0.035 | I31: =B34 -> 0.035 | J31: =B34 -> 0.035 | K31: =B34 -> 0.035 | L31: =B34 -> 0.035 | M31: =B34 -> 0.035
A32: ="Transaktionsgebyr ("&B5&")" -> Transaktionsgebyr (DKK) | B32: 1.8 | C32: 1.8 | D32: 1.8 | E32: 1.8 | F32: 1.8 | G32: 1.8 | H32: 1.8 | I32: 1.8 | J32: 1.8 | K32: 1.8 | L32: 1.8 | M32: 1.8
A34: Betalingsgate | B34: 0.035
A37: Topix medlemmer | B37: Pris pr år | C37: Indtægt | D37: Antal abb | E37: Pris ex. moms
A38: 1 | B38: =E38*125% -> 6237.5 | C38: =B51*A38*B38 -> 623750 | D38: =B51*A38 -> 100 | E38: 4990
A39: 0 | B39: =E39*125% -> 37500 | C39: =B50*A39*B39 -> 0 | D39: =B51*A39 -> 0 | E39: =E45*75% -> 30000
A40: 0 | B40: =E40*125% -> 31250 | C40: =B44*A40*B40 -> 0 | D40: =B51*A40 -> 0 | E40: =E46*50% -> 25000
A43: Boardroom | B43: Pris pr år | C43: Indtægt | D43: Antal abb | E43: Pris ex. moms
A44: 0.25 | B44: =E44*125% -> 37500 | C44: =B50*A44*B44 -> 375000 | D44: =B50*A44 -> 10 | E44: 30000
A45: 0.75 | B45: =E45*125% -> 50000 | C45: =B50*A45*B45 -> 1500000 | D45: =B50*A45 -> 30 | E45: 40000
A46: 0 | B46: =E46*125% -> 62500 | C46: =B50*A46*B46 -> 0 | D46: =B50*A46 -> 0 | E46: 50000
A48: =SUM(A44:A46) -> 1
A49: Total indtægt år 1
A50: Antal medlemmer Boardroom | B50: 40 | C50: =SUM(C44:C46) -> 1875000
A51: Antal medlemmer Topix | B51: 100 | C51: =SUM(C38:C40) -> 623750
...

Sheet Budget2025
A1: ="Budget "&'Opsætning2025'!$B$6 -> Budget 2025
A2: ='Opsætning2025'!$B$4 -> Topix.dk ApS
A4: ="Alle beløb er i "&'Opsætning2025'!B5&" og ex. moms" -> Alle beløb er i DKK og ex. moms | B4: =PROPER('Opsætning2025'!B$10) -> Januar-25 | C4: =PROPER('Opsætning2025'!C$10) -> Februar-25 | D4: =PROPER('Opsætning2025'!D$10) -> Marts-25 | E4: =PROPER('Opsætning2025'!E$10) -> April-25 | F4: =PROPER('Opsætning2025'!F$10) -> Maj-25 | G4: =PROPER('Opsætning2025'!G$10) -> Juni-25 | H4: =PROPER('Opsætning2025'!H$10) -> Juli-25 | I4: =PROPER('Opsætning2025'!I$10) -> August-25 | ... M4: =PROPER('Opsætning2025'!M$10) -> December-25 | O4: Årstotal
A5: Omsætning
A6: Topix salg | B6: =SUM('Opsætning2025'!B13*'Opsætning2025'!B15) -> 0 | C6: =SUM('Opsætning2025'!C13*'Opsætning2025'!C15) -> 0 | D6: =SUM('Opsætning2025'!D13*'Opsætning2025'!D15) -> 10000 | E6: =SUM('Opsætning2025'!E13*'Opsætning2025'!E15) -> 20000 | F6: =SUM('Opsætning2025'!F13*'Opsætning2025'!F15) -> 20000 | G6: =SUM('Opsætning2025'!G13*'Opsætning2025'!G15) -> 20000 | H6: =SUM('Opsætning2025'!H13*'Opsætning2025'!H15) -> 20000 | I6: =SUM('Opsætning2025'!I13*'Opsætning2025'!I15) -> 100000 | ... M6: =SUM('Opsætning2025'!M13*'Opsætning2025'!M15) -> 100000 | O6: =SUM(B6:M6) -> 590000
A7: Boardroom salg | B7: =SUM('Opsætning2025'!B14*'Opsætning2025'!B16) -> 0 | C7: =SUM('Opsætning2025'!C14*'Opsætning2025'!C16) -> 0 | D7: =SUM('Opsætning2025'!D14*'Opsætning2025'!D16) -> 0 | E7: =SUM('Opsætning2025'!E14*'Opsætning2025'!E16) -> 240000 | F7: =SUM('Opsætning2025'!F14*'Opsætning2025'!F16) -> 280000 | G7: =SUM('Opsætning2025'!G14*'Opsætning2025'!G16) -> 80000 | H7: =SUM('Opsætning2025'!H14*'Opsætning2025'!H16) -> 0 | I7: =SUM('Opsætning2025'!I14*'Opsætning2025'!I16) -> 240000 | ... M7: =SUM('Opsætning2025'!M14*'Opsætning2025'!M16) -> 120000 | O7: =SUM(B7:M7) -> 1520000
A8: Direkte omkostninger
A9: D2C Vareforbrug | O9: =SUM(B9:M9) -> 0
A10: D2C Fragt & emballage | O10: =SUM(B10:M10) -> 0
A11: B2B Vareforbrug | O11: =SUM(B11:M11) -> 0
A12: B2B Fragt & emballage | O12: =SUM(B12:M12) -> 0
A13: Dækningsbidrag | B13: =SUM(B6:B12) -> 0 | C13: =SUM(C6:C12) -> 0 | D13: =SUM(D6:D12) -> 10000 | E13: =SUM(E6:E12) -> 260000 | F13: =SUM(F6:F12) -> 300000 | G13: =SUM(G6:G12) -> 100000 | H13: =SUM(H6:H12) -> 20000 | I13: =SUM(I6:I12) -> 340000 | ... M13: =SUM(M6:M12) -> 220000 | O13: =SUM(B13:M13) -> 2110000
A14: Bruttomargin | B14: 0 | C14: 0 | D14: =D13/SUM(D6:D7) -> 1 | E14: =E13/SUM(E6:E7) -> 1 | F14: =F13/SUM(F6:F7) -> 1 | G14: =G13/SUM(G6:G7) -> 1 | H14: =H13/SUM(H6:H7) -> 1 | I14: =I13/SUM(I6:I7) -> 1 | J14: =J13/SUM(J6:J7) -> 1 | K14: =K13/SUM(K6:K7) -> 1 | ... M14: =M13/SUM(M6:M7) -> 1
A16: Variable omkostninger
A17: Marketing | B17: =-('Opsætning2025'!B19+'Opsætning2025'!B20) -> 0 | C17: =-('Opsætning2025'!C19+'Opsætning2025'!C20) -> -21000 | D17: =-('Opsætning2025'!D19+'Opsætning2025'!D20) -> -2313 | E17: =-('Opsætning2025'!E19+'Opsætning2025'!E20) -> 0 | F17: =-('Opsætning2025'!F19+'Opsætning2025'!F20) -> -15000 | G17: =-('Opsætning2025'!G19+'Opsætning2025'!G20) -> -10000 | H17: =-('Opsætning2025'!H19+'Opsætning2025'!H20) -> -10000 | I17: =-('Opsætning2025'!I19+'Opsætning2025'!I20) -> -15000 | ... M17: =-('Opsætning2025'!M19+'Opsætning2025'!M20) -> -21000 | O17: =SUM(B17:M17) -> -157313
A18: Betalingshåndtering | B18: =-('Opsætning2025'!B$30+('Opsætning2025'!B$13*('Opsætning2025'!B$32+('Opsætning2025'!B$16*'Opsætning2025'!B$31)))) -> 0 | C18: =-('Opsætning2025'!C$30+('Opsætning2025'!C$13*('Opsætning2025'!C$32+('Opsætning2025'!C$16*'Opsætning2025'!C$31)))) -> 0 | D18: =-('Opsætning2025'!D$30+('Opsætning2025'!D$13*('Opsætning2025'!D$32+('Opsætning2025'!D$16*'Opsætning2025'!D$31)))) -> -3.6 | E18: =-('Opsætning2025'!E$30+('Opsætning2025'!E$13*('Opsætning2025'!E$32+('Opsætning2025'!E$16*'Opsætning2025'!E$31)))) -> -4207.2 | F18: =-('Opsætning2025'!F$30+('Opsætning2025'!F$13*('Opsætning2025'!F$32+('Opsætning2025'!F$16*'Opsætning2025'!F$31)))) -> -5607.2 | G18: =-('Opsætning2025'!G$30+('Opsætning2025'!G$13*('Opsætning2025'!G$32+('Opsætning2025'!G$16*'Opsætning2025'!G$31)))) -> -5607.2 | H18: =-('Opsætning2025'!H$30+('Opsætning2025'!H$13*('Opsætning2025'!H$32+('Opsætning2025'!H$16*'Opsætning2025'!H$31)))) -> -5607.2 | I18: =-('Opsætning2025'!I$30+('Opsætning2025'!I$13*('Opsætning2025'!I$32+('Opsætning2025'!I$16*'Opsætning2025'!I$31)))) -> -28036 | ... M18: =-('Opsætning2025'!M$30+('Opsætning2025'!M$13*('Opsætning2025'!M$32+('Opsætning2025'!M$16*'Opsætning2025'!M$31)))) -> -28036 | O18: =SUM(B18:M18) -> -161212.4
A19: Contentproduktion | B19: -90000 | C19: -45000 | D19: -45000 | E19: -5000 | F19: 0 | G19: 0 | H19: 0 | I19: 0 | J19: 0 | K19: 0 | L19: 0 | M19: 0 | O19: =SUM(B19:M19) -> -185000
A20: Repræsentation | F20: -2000 | G20: -2000 | H20: -2000 | I20: -2000 | J20: -2000 | K20: -2000 | L20: -2000 | M20: -2000 | O20: =SUM(B20:M20) -> -16000
A21: Kundekompensation | B21: =-(B6*'Opsætning2025'!B$26) -> 0 | C21: =-(C6*'Opsætning2025'!C$26) -> 0 | D21: =-(D6*'Opsætning2025'!D$26) -> 0 | E21: =-(E6*'Opsætning2025'!E$26) -> 0 | F21: =-(F6*'Opsætning2025'!F$26) -> 0 | G21: =-(G6*'Opsætning2025'!G$26) -> 0 | H21: =-(H6*'Opsætning2025'!H$26) -> 0 | I21: =-(I6*'Opsætning2025'!I$26) -> 0 | ... M21: =-(M6*'Opsætning2025'!M$26) -> 0 | O21: =SUM(B21:M21) -> 0
A22: Medarbejdere
A23: Løn | B23: 0 | C23: 0 | D23: 0 | E23: =-18640*2 -> -37280 | F23: -50000 | G23: -50000 | H23: -50000 | I23: -50000 | J23: -60000 | K23: -70000 | L23: -80000 | M23: -80000 | O23: =SUM(B23:M23) -> -527280
A24: Casper Edens | C24: 0 | D24: 0 | E24: =E13*15%*-1 -> -39000 | F24: =F13*15%*-1 -> -45000 | G24: =G13*15%*-1 -> -15000 | H24: =H13*15%*-1 -> -3000 | I24: =I13*15%*-1 -> -51000 | J24: =J13*15%*-1 -> -51000 | K24: =K13*15%*-1 -> -45000 | L24: =L13*15%*-1 -> -33000 | M24: =M13*15%*-1 -> -33000 | O24: =SUM(B24:M24) -> -315000
A25: Lønrelaterede omkostninger | B25: =B23*'Opsætning2025'!$B$8 -> 0 | C25: =C23*'Opsætning2025'!$B$8 -> 0 | D25: =D23*'Opsætning2025'!$B$8 -> 0 | E25: =E23*'Opsætning2025'!$B$8 -> -5964.8 | F25: =F23*'Opsætning2025'!$B$8 -> -8000 | G25: =G23*'Opsætning2025'!$B$8 -> -8000 | H25: =H23*'Opsætning2025'!$B$8 -> -8000 | I25: =I23*'Opsætning2025'!$B$8 -> -8000 | ... M25: =M23*'Opsætning2025'!$B$8 -> -12800 | O25: =SUM(B25:M25) -> -84364.8
A26: Medarbejderpleje | B26: -500 | C26: -500 | D26: -500 | E26: -500 | F26: -500 | G26: -500 | H26: -500 | I26: -500 | J26: -500 | K26: -500 | L26: -500 | M26: -500 | O26: =SUM(B26:M26) -> -6000
A27: Shop & IT
A28: Platform (website & Circle.so) | B28: -25000 | C28: 0 | D28: 0 | E28: 0 | F28: 0 | G28: 0 | H28: 0 | I28: 0 | J28: 0 | K28: 0 | L28: 0 | M28: 0 | O28: =SUM(B28:M28) -> -25000
A29: Udvikling, design & vedligeholdelse | B29: -100000 | C29: -30000 | D29: -20000 | E29: -5000 | F29: -5000 | G29: -5000 | H29: -5000 | I29: -5000 | J29: -5000 | K29: -5000 | L29: -5000 | M29: -5000 | O29: =SUM(B29:M29) -> -195000
A30: Hosting & Domæne | B30: -500 | C30: -500 | D30: -500 | E30: -500 | F30: -500 | G30: -500 | H30: -500 | I30: -500 | J30: -500 | K30: -500 | L30: -500 | M30: -500 | O30: =SUM(B30:M30) -> -6000
A31: Stape | B31: -155 | C31: -155 | D31: -155 | E31: -155 | F31: -155 | G31: -155 | H31: -155 | I31: -155 | J31: -155 | K31: -155 | L31: -155 | M31: -155 | O31: =SUM(B31:M31) -> -1860
A32: Zoom | D32: -703 | E32: -118 | F32: -585 | O32: =SUM(B32:M32) -> -1406
A33: Cloudflare | B33: -275 | C33: -275 | D33: -275 | E33: -275 | F33: -275 | G33: -275 | H33: -275 | I33: -275 | J33: -275 | K33: -275 | L33: -275 | M33: -275 | O33: =SUM(B33:M33) -> -3300
A34: Klayvio | C34: -220 | D34: -212 | E34: -315 | F34: -410 | O34: =SUM(B34:M34) -> -1157
A35: Cookieinformation | C35: -1713 | O35: =SUM(B35:M35) -> -1713
A36: Google Workspace | E36: -446 | F36: -446 | G36: -446 | H36: -446 | I36: -446 | J36: -446 | K36: -446 | L36: -446 | M36: -446 | O36: =SUM(B36:M36) -> -4014
A37: Kingsta | B37: -237 | C37: -237 | D37: -237 | E37: -237 | F37: -237 | G37: -237 | H37: -237 | I37: -237 | J37: -237 | K37: -237 | L37: -237 | M37: -237 | O37: =SUM(B37:M37) -> -2844
A38: Corpay | B38: -100 | C38: -100 | D38: -100 | E38: -100 | F38: -100 | G38: -100 | H38: -100 | I38: -100 | J38: -100 | K38: -100 | L38: -100 | M38: -100 | O38: =SUM(B38:M38) -> -1200
A39: Slack | E39: -31 | F39: -31 | G39: -31 | H39: -31 | I39: -31 | J39: -31 | K39: -31 | L39: -31 | M39: -31 | O39: =SUM(B39:M39) -> -279
A40: Monday | B40: -6500 | C40: -3871 | F40: -240 | G40: -240 | H40: -240 | I40: -240 | J40: -240 | K40: -240 | L40: -240 | M40: -240 | O40: =SUM(B40:M40) -> -12291
A41: Loom | F41: -2500 | O41: =SUM(B41:M41) -> -2500
A42: Riverside | C42: -2500 | O42: =SUM(B42:M42) -> -2500
...

Sheet Opsætning2026
A1: Opsætning
A3: Generelt
A4: Virksomhed | B4: Topix.dk ApS
A5: Valuta | B5: DKK
A6: Budgetår | B6: 2026
A7: Momssats | B7: 0.25 | C7: =B7+1 -> 1.25
A8: Lønrelaterede omkostninger (feriepenge + div.) | B8: 0.16
A10: Måneder | B10: januar-26 | C10: februar-26 | D10: marts-26 | E10: april-26 | F10: maj-26 | G10: juni-26 | H10: juli-26 | I10: august-26 | J10: september-26 | K10: oktober-26 | L10: november-26 | M10: december-26 | N10: Total
A11: Dage i måned | B11: =DAY(EOMONTH(B$10,0)) -> 31 | C11: =DAY(EOMONTH(C$10,0)) -> 28 | D11: =DAY(EOMONTH(D$10,0)) -> 31 | E11: =DAY(EOMONTH(E$10,0)) -> 30 | F11: =DAY(EOMONTH(F$10,0)) -> 31 | G11: =DAY(EOMONTH(G$10,0)) -> 30 | H11: =DAY(EOMONTH(H$10,0)) -> 31 | I11: =DAY(EOMONTH(I$10,0)) -> 31 | ... M11: =DAY(EOMONTH(M$10,0)) -> 31
A12: Omsætning
A13: B2C Ordrer | B13: =($D$53+$D$45)/12 -> 40.25 | C13: =($D$53+$D$45)/12 -> 40.25 | D13: =($D$53+$D$45)/12 -> 40.25 | E13: =($D$53+$D$45)/12 -> 40.25 | F13: =($D$53+$D$45)/12 -> 40.25 | G13: =($D$53+$D$45)/12 -> 40.25 | H13: =($D$53+$D$45)/12 -> 40.25 | I13: =($D$53+$D$45)/12 -> 40.25 | ... M13: =($D$53+$D$45)/12 -> 40.25 | N13: =SUM(B13:M13) -> 483
A14: Gns. Produkter per B2C ordre | B14: 1 | C14: 1 | D14: 1 | E14: 1 | F14: 1 | G14: 1 | H14: 1 | I14: 1 | J14: 1 | K14: 1 | L14: 1 | M14: 1
A15: Gns. B2C Ordreværdi (inkl. moms) | B15: =SUM($C$54) -> 24987.5 | C15: =SUM($C$54) -> 24987.5 | D15: =SUM($C$54) -> 24987.5 | E15: =SUM($C$54) -> 24987.5 | F15: =SUM($C$54) -> 24987.5 | G15: =SUM($C$54) -> 24987.5 | H15: =SUM($C$54) -> 24987.5 | I15: =SUM($C$54) -> 24987.5 | ... M15: =SUM($C$54) -> 24987.5
A16: Gns. B2C Fortjeneste | B16: 1 | C16: 1 | D16: 1 | E16: 1 | F16: 1 | G16: 1 | H16: 1 | I16: 1 | J16: 1 | K16: 1 | L16: 1 | M16: 1
A17: B2B Salg (ex. moms) | B17: 0 | C17: 0 | D17: 0 | E17: 0 | F17: 0 | G17: 0 | H17: 0 | I17: 0 | J17: 0 | K17: 0 | L17: 0 | M17: 0
A18: Gns. B2B Fortjeneste | B18: 0 | C18: 0 | D18: 0 | E18: 0 | F18: 0 | G18: 0 | H18: 0 | I18: 0 | J18: 0 | K18: 0 | L18: 0 | M18: 0
A20: Marketing
A21: Marketingspend | B21: 40000 | C21: 40000 | D21: 40000 | E21: 40000 | F21: 40000 | G21: 40000 | H21: 40000 | I21: 40000 | J21: 40000 | K21: 40000 | L21: 40000 | M21: 40000 | N21: =SUM(B21:M21) -> 480000
A22: Spend Management | B22: 20000 | C22: 20000 | D22: 20000 | E22: 20000 | F22: 20000 | G22: 20000 | H22: 20000 | I22: 20000 | J22: 20000 | K22: 20000 | L22: 20000 | M22: 20000 | N22: =SUM(B22:M22) -> 240000
A23: Gns. pris per kunde | B23: =B21/B24 -> 993.78882 | C23: =C21/C24 -> 993.78882 | D23: =D21/D24 -> 993.78882 | E23: =E21/E24 -> 993.78882 | F23: =F21/F24 -> 993.78882 | G23: =G21/G24 -> 993.78882 | H23: =H21/H24 -> 993.78882 | I23: =I21/I24 -> 993.78882 | ... M23: =M21/M24 -> 993.78882 | N23: =SUM(B23:M23)/12 -> 993.78882
A24: Kunder købt | B24: =B13 -> 40.25 | C24: =C13 -> 40.25 | D24: =D13 -> 40.25 | E24: =E13 -> 40.25 | F24: =F13 -> 40.25 | G24: =G13 -> 40.25 | H24: =H13 -> 40.25 | I24: =I13 -> 40.25 | ... M24: =M13 -> 40.25 | N24: =SUM(B24:M24) -> 483
A25: Købte kunder (%) | B25: =B24/B13 -> 1 | C25: =C24/C13 -> 1 | D25: =D24/D13 -> 1 | E25: =E24/E13 -> 1 | F25: =F24/F13 -> 1 | G25: =G24/G13 -> 1 | H25: =H24/H13 -> 1 | I25: =I24/I13 -> 1 | ... M25: =M24/M13 -> 1
A26: Organiske kunder (%) | B26: =1-B25 -> 0 | C26: =1-C25 -> 0 | D26: =1-D25 -> 0 | E26: =1-E25 -> 0 | F26: =1-F25 -> 0 | G26: =1-G25 -> 0 | H26: =1-H25 -> 0 | I26: =1-I25 -> 0 | ... M26: =1-M25 -> 0
A28: Logistik & Fragt
A29: Gns. fragtpris per D2C ordre | B29: 0 | C29: 0 | D29: 0 | E29: 0 | F29: 0 | G29: 0 | H29: 0 | I29: 0 | J29: 0 | K29: 0 | L29: 0 | M29: 0
A30: Gns. emballagepris per D2C ordre (inkl pluk/pak) | B30: 0 | C30: 0 | D30: 0 | E30: 0 | F30: 0 | G30: 0 | H30: 0 | I30: 0 | J30: 0 | K30: 0 | L30: 0 | M30: 0
A31: Returgebyr ved uafhentet pakke | B31: 0 | C31: 0 | D31: 0 | E31: 0 | F31: 0 | G31: 0 | H31: 0 | I31: 0 | J31: 0 | K31: 0 | L31: 0 | M31: 0
A32: Returprocent | B32: 0 | C32: 0 | D32: 0 | E32: 0 | F32: 0 | G32: 0 | H32: 0 | I32: 0 | J32: 0 | K32: 0 | L32: 0 | M32: 0
A33: B2B Fragt | B33: 0 | C33: 0 | D33: 0 | E33: 0 | F33: 0 | G33: 0 | H33: 0 | I33: 0 | J33: 0 | K33: 0 | L33: 0 | M33: 0
A35: Betalingshåndtering
A36: Abonnement | B36: 0 | C36: 0 | D36: 0 | E36: 0 | F36: 0 | G36: 0 | H36: 0 | I36: 0 | J36: 0 | K36: 0 | L36: 0 | M36: 0
A37: Betalingsgebyr (%) | B37: =$B59 -> 0.051 | C37: =$B59 -> 0.051 | D37: =$B59 -> 0.051 | E37: =$B59 -> 0.051 | F37: =$B59 -> 0.051 | G37: =$B59 -> 0.051 | H37: =$B59 -> 0.051 | I37: =$B59 -> 0.051 | ... M37: =$B59 -> 0.051
A38: ="Transaktionsgebyr ("&B5&")" -> Transaktionsgebyr (DKK) | B38: 1 | C38: 1 | D38: 1 | E38: 1 | F38: 1 | G38: 1 | H38: 1 | I38: 1 | J38: 1 | K38: 1 | L38: 1 | M38: 1
A41: Brugere der forlænger aftale | B41: Pris pr år | C41: Indtægt | D41: Antal abb | E41: Pris ex. moms
A42: 0.3 | B42: =E42*125% -> 24987.5 | C42: =B42*D42 -> 824587.5 | D42: =('Opsætning2025'!D38+'Opsætning2025'!D44)*A42 -> 33 | E42: =E48 -> 19990
A43: 0 | B43: =E43*125% -> 15618.75 | C43: =B43*D43 -> 0 | D43: =('Opsætning2025'!D39+'Opsætning2025'!D45)*A43 -> 0 | E43: =E49*50% -> 12495
B44: =E44*125% -> 0 | C44: =B50*A44*B44 -> 0 | D44: =B50*A44 -> 0
D45: =SUM(D42:D44) -> 33
A47: Nye brugere | B47: Pris pr år | C47: Indtægt | D47: Antal abb | E47: Pris ex. moms
A48: 1 | B48: =E48*125% -> 24987.5 | C48: =D53*A48*B48 -> 11244375 | D48: =D53*A48 -> 450 | E48: 19990
...

Sheet Budget2026
A1: ="Budget "&'Opsætning2026'!$B$6 -> Budget 2026
A2: ='Opsætning2026'!$B$4 -> Topix.dk ApS
A4: ="Alle beløb er i "&'Opsætning2025'!B5&" og ex. moms" -> Alle beløb er i DKK og ex. moms | B4: =PROPER('Opsætning2026'!B$10) -> Januar-26 | C4: =PROPER('Opsætning2026'!C$10) -> Februar-26 | D4: =PROPER('Opsætning2026'!D$10) -> Marts-26 | E4: =PROPER('Opsætning2026'!E$10) -> April-26 | F4: =PROPER('Opsætning2026'!F$10) -> Maj-26 | G4: =PROPER('Opsætning2026'!G$10) -> Juni-26 | H4: =PROPER('Opsætning2026'!H$10) -> Juli-26 | I4: =PROPER('Opsætning2026'!I$10) -> August-26 | ... M4: =PROPER('Opsætning2026'!M$10) -> December-26 | O4: Årstotal
A5: Omsætning
A6: D2C Salg | B6: =('Opsætning2026'!B$13*'Opsætning2026'!B$15)/'Opsætning2026'!$C$7 -> 804597.5 | C6: =('Opsætning2026'!C$13*'Opsætning2026'!C$15)/'Opsætning2026'!$C$7 -> 804597.5 | D6: =('Opsætning2026'!D$13*'Opsætning2026'!D$15)/'Opsætning2026'!$C$7 -> 804597.5 | E6: =('Opsætning2026'!E$13*'Opsætning2026'!E$15)/'Opsætning2026'!$C$7 -> 804597.5 | F6: =('Opsætning2026'!F$13*'Opsætning2026'!F$15)/'Opsætning2026'!$C$7 -> 804597.5 | G6: =('Opsætning2026'!G$13*'Opsætning2026'!G$15)/'Opsætning2026'!$C$7 -> 804597.5 | H6: =('Opsætning2026'!H$13*'Opsætning2026'!H$15)/'Opsætning2026'!$C$7 -> 804597.5 | I6: =('Opsætning2026'!I$13*'Opsætning2026'!I$15)/'Opsætning2026'!$C$7 -> 804597.5 | ... M6: =('Opsætning2026'!M$13*'Opsætning2026'!M$15)/'Opsætning2026'!$C$7 -> 804597.5 | O6: =SUM(B6:M6) -> 9655170
A7: B2B Salg | B7: ='Opsætning2026'!B17 -> 0 | C7: ='Opsætning2026'!C17 -> 0 | D7: ='Opsætning2026'!D17 -> 0 | E7: ='Opsætning2026'!E17 -> 0 | F7: ='Opsætning2026'!F17 -> 0 | G7: ='Opsætning2026'!G17 -> 0 | H7: ='Opsætning2026'!H17 -> 0 | I7: ='Opsætning2026'!I17 -> 0 | ... M7: ='Opsætning2026'!M17 -> 0 | O7: =SUM(B7:M7) -> 0
A8: Direkte omkostninger
A9: D2C Vareforbrug | B9: =-(B$6*(1-'Opsætning2026'!B$16)) -> 0 | C9: =-(C$6*(1-'Opsætning2026'!C$16)) -> 0 | D9: =-(D$6*(1-'Opsætning2026'!D$16)) -> 0 | E9: =-(E$6*(1-'Opsætning2026'!E$16)) -> 0 | F9: =-(F$6*(1-'Opsætning2026'!F$16)) -> 0 | G9: =-(G$6*(1-'Opsætning2026'!G$16)) -> 0 | H9: =-(H$6*(1-'Opsætning2026'!H$16)) -> 0 | I9: =-(I$6*(1-'Opsætning2026'!I$16)) -> 0 | ... M9: =-(M$6*(1-'Opsætning2026'!M$16)) -> 0 | O9: =SUM(B9:M9) -> 0
A10: D2C Fragt & emballage | B10: =-('Opsætning2026'!B$13*('Opsætning2026'!B$29+'Opsætning2026'!B$30)) -> 0 | C10: =-('Opsætning2026'!C$13*('Opsætning2026'!C$29+'Opsætning2026'!C$30)) -> 0 | D10: =-('Opsætning2026'!D$13*('Opsætning2026'!D$29+'Opsætning2026'!D$30)) -> 0 | E10: =-('Opsætning2026'!E$13*('Opsætning2026'!E$29+'Opsætning2026'!E$30)) -> 0 | F10: =-('Opsætning2026'!F$13*('Opsætning2026'!F$29+'Opsætning2026'!F$30)) -> 0 | G10: =-('Opsætning2026'!G$13*('Opsætning2026'!G$29+'Opsætning2026'!G$30)) -> 0 | H10: =-('Opsætning2026'!H$13*('Opsætning2026'!H$29+'Opsætning2026'!H$30)) -> 0 | I10: =-('Opsætning2026'!I$13*('Opsætning2026'!I$29+'Opsætning2026'!I$30)) -> 0 | ... M10: =-('Opsætning2026'!M$13*('Opsætning2026'!M$29+'Opsætning2026'!M$30)) -> 0 | O10: =SUM(B10:M10) -> 0
A11: B2B Vareforbrug | B11: =-('Opsætning2026'!B17*(1-'Opsætning2026'!B18)) -> 0 | C11: =-('Opsætning2026'!C17*(1-'Opsætning2026'!C18)) -> 0 | D11: =-('Opsætning2026'!D17*(1-'Opsætning2026'!D18)) -> 0 | E11: =-('Opsætning2026'!E17*(1-'Opsætning2026'!E18)) -> 0 | F11: =-('Opsætning2026'!F17*(1-'Opsætning2026'!F18)) -> 0 | G11: =-('Opsætning2026'!G17*(1-'Opsætning2026'!G18)) -> 0 | H11: =-('Opsætning2026'!H17*(1-'Opsætning2026'!H18)) -> 0 | I11: =-('Opsætning2026'!I17*(1-'Opsætning2026'!I18)) -> 0 | ... M11: =-('Opsætning2026'!M17*(1-'Opsætning2026'!M18)) -> 0 | O11: =SUM(B11:M11) -> 0
A12: B2B Fragt & emballage | B12: =-('Opsætning2026'!B33) -> 0 | C12: =-('Opsætning2026'!C33) -> 0 | D12: =-('Opsætning2026'!D33) -> 0 | E12: =-('Opsætning2026'!E33) -> 0 | F12: =-('Opsætning2026'!F33) -> 0 | G12: =-('Opsætning2026'!G33) -> 0 | H12: =-('Opsætning2026'!H33) -> 0 | I12: =-('Opsætning2026'!I33) -> 0 | ... M12: =-('Opsætning2026'!M33) -> 0 | O12: =SUM(B12:M12) -> 0
A13: Dækningsbidrag | B13: =SUM(B6:B12) -> 804597.5 | C13: =SUM(C6:C12) -> 804597.5 | D13: =SUM(D6:D12) -> 804597.5 | E13: =SUM(E6:E12) -> 804597.5 | F13: =SUM(F6:F12) -> 804597.5 | G13: =SUM(G6:G12) -> 804597.5 | H13: =SUM(H6:H12) -> 804597.5 | I13: =SUM(I6:I12) -> 804597.5 | ... M13: =SUM(M6:M12) -> 804597.5 | O13: =SUM(B13:M13) -> 9655170
A14: Bruttomargin | B14: 0 | C14: =C13/SUM(C6:C7) -> 1 | D14: =D13/SUM(D6:D7) -> 1 | E14: =E13/SUM(E6:E7) -> 1 | F14: =F13/SUM(F6:F7) -> 1 | G14: =G13/SUM(G6:G7) -> 1 | H14: =H13/SUM(H6:H7) -> 1 | I14: =I13/SUM(I6:I7) -> 1 | J14: =J13/SUM(J6:J7) -> 1 | ... M14: =M13/SUM(M6:M7) -> 1
A16: Variable omkostninger
A17: Marketing | B17: =-('Opsætning2026'!B21+'Opsætning2026'!B22) -> -60000 | C17: =-('Opsætning2026'!C21+'Opsætning2026'!C22) -> -60000 | D17: =-('Opsætning2026'!D21+'Opsætning2026'!D22) -> -60000 | E17: =-('Opsætning2026'!E21+'Opsætning2026'!E22) -> -60000 | F17: =-('Opsætning2026'!F21+'Opsætning2026'!F22) -> -60000 | G17: =-('Opsætning2026'!G21+'Opsætning2026'!G22) -> -60000 | H17: =-('Opsætning2026'!H21+'Opsætning2026'!H22) -> -60000 | I17: =-('Opsætning2026'!I21+'Opsætning2026'!I22) -> -60000 | ... M17: =-('Opsætning2026'!M21+'Opsætning2026'!M22) -> -60000 | O17: =SUM(B17:M17) -> -720000
A18: Betalingshåndtering | B18: =-('Opsætning2026'!B$36+('Opsætning2026'!B$13*('Opsætning2026'!B$38+('Opsætning2026'!B$15*'Opsætning2026'!B$37)))) -> -51333.341 | C18: =-('Opsætning2026'!C$36+('Opsætning2026'!C$13*('Opsætning2026'!C$38+('Opsætning2026'!C$15*'Opsætning2026'!C$37)))) -> -51333.341 | D18: =-('Opsætning2026'!D$36+('Opsætning2026'!D$13*('Opsætning2026'!D$38+('Opsætning2026'!D$15*'Opsætning2026'!D$37)))) -> -51333.341 | E18: =-('Opsætning2026'!E$36+('Opsætning2026'!E$13*('Opsætning2026'!E$38+('Opsætning2026'!E$15*'Opsætning2026'!E$37)))) -> -51333.341 | F18: =-('Opsætning2026'!F$36+('Opsætning2026'!F$13*('Opsætning2026'!F$38+('Opsætning2026'!F$15*'Opsætning2026'!F$37)))) -> -51333.341 | G18: =-('Opsætning2026'!G$36+('Opsætning2026'!G$13*('Opsætning2026'!G$38+('Opsætning2026'!G$15*'Opsætning2026'!G$37)))) -> -51333.341 | H18: =-('Opsætning2026'!H$36+('Opsætning2026'!H$13*('Opsætning2026'!H$38+('Opsætning2026'!H$15*'Opsætning2026'!H$37)))) -> -51333.341 | I18: =-('Opsætning2026'!I$36+('Opsætning2026'!I$13*('Opsætning2026'!I$38+('Opsætning2026'!I$15*'Opsætning2026'!I$37)))) -> -51333.341 | ... M18: =-('Opsætning2026'!M$36+('Opsætning2026'!M$13*('Opsætning2026'!M$38+('Opsætning2026'!M$15*'Opsætning2026'!M$37)))) -> -51333.341 | O18: =SUM(B18:M18) -> -616000.09
A19: Contentproduktion | B19: -25000 | C19: -25000 | D19: -25000 | E19: -25000 | F19: -25000 | G19: -25000 | H19: -25000 | I19: -25000 | J19: -25000 | K19: -25000 | L19: -25000 | M19: -25000 | O19: =SUM(B19:M19) -> -300000
A20: Repræsentation | B20: -4000 | C20: -4000 | D20: -4000 | E20: -4000 | F20: -4000 | G20: -4000 | H20: -4000 | I20: -4000 | J20: -4000 | K20: -4000 | L20: -4000 | M20: -4000 | O20: =SUM(B20:M20) -> -48000
A21: Kundekompensation | B21: =-(B6*'Opsætning2026'!B$32) -> 0 | C21: =-(C6*'Opsætning2026'!C$32) -> 0 | D21: =-(D6*'Opsætning2026'!D$32) -> 0 | E21: =-(E6*'Opsætning2026'!E$32) -> 0 | F21: =-(F6*'Opsætning2026'!F$32) -> 0 | G21: =-(G6*'Opsætning2026'!G$32) -> 0 | H21: =-(H6*'Opsætning2026'!H$32) -> 0 | I21: =-(I6*'Opsætning2026'!I$32) -> 0 | ... M21: =-(M6*'Opsætning2026'!M$32) -> 0 | O21: =SUM(B21:M21) -> 0
A22: Medarbejdere
A23: Løn | B23: -200000 | C23: -200000 | D23: -200000 | E23: -200000 | F23: -200000 | G23: -200000 | H23: -200000 | I23: -200000 | J23: -200000 | K23: -200000 | L23: -200000 | M23: -200000 | O23: =SUM(B23:M23) -> -2400000
A24: Lønrelaterede omkostninger | B24: =B23*'Opsætning2026'!$B$8 -> -32000 | C24: =C23*'Opsætning2025'!$B$8 -> -32000 | D24: =D23*'Opsætning2025'!$B$8 -> -32000 | E24: =E23*'Opsætning2025'!$B$8 -> -32000 | F24: =F23*'Opsætning2025'!$B$8 -> -32000 | G24: =G23*'Opsætning2025'!$B$8 -> -32000 | H24: =H23*'Opsætning2025'!$B$8 -> -32000 | I24: =I23*'Opsætning2025'!$B$8 -> -32000 | J24: =J23*'Opsætning2025'!$B$8 -> -32000 | ... M24: =M23*'Opsætning2025'!$B$8 -> -32000 | O24: =SUM(B24:M24) -> -384000
A25: Medarbejderpleje | B25: -500 | C25: -500 | D25: -500 | E25: -500 | F25: -500 | G25: -500 | H25: -500 | I25: -500 | J25: -500 | K25: -500 | L25: -500 | M25: -500 | O25: =SUM(B25:M25) -> -6000
A26: Shop & IT
A27: Platform (website & Circle.so) | B27: -2000 | C27: -2000 | D27: -2000 | E27: -2000 | F27: -2000 | G27: -2000 | H27: -2000 | I27: -2000 | J27: -2000 | K27: -2000 | L27: -2000 | M27: -2000 | O27: =SUM(B27:M27) -> -24000
A28: Udvikling & vedligeholdelse | B28: -5000 | C28: -5000 | D28: -5000 | E28: -5000 | F28: -5000 | G28: -5000 | H28: -5000 | I28: -5000 | J28: -5000 | K28: -5000 | L28: -5000 | M28: -5000 | O28: =SUM(B28:M28) -> -60000
A29: Hosting & Domæne | B29: -500 | C29: -500 | D29: -500 | E29: -500 | F29: -500 | G29: -500 | H29: -500 | I29: -500 | J29: -500 | K29: -500 | L29: -500 | M29: -500 | O29: =SUM(B29:M29) -> -6000
A30: Software og abonnementer | B30: -300 | C30: -300 | D30: -300 | E30: -300 | F30: -300 | G30: -300 | H30: -300 | I30: -300 | J30: -300 | K30: -300 | L30: -300 | M30: -300 | O30: =SUM(B30:M30) -> -3600
A31: Lokaler
A32: Kontorleje | B32: -1450 | C32: -1450 | D32: -1450 | E32: -1450 | F32: -1450 | G32: -1450 | H32: -1450 | I32: -1450 | J32: -1450 | K32: -1450 | L32: -1450 | M32: -1450 | O32: =SUM(B32:M32) -> -17400
A33: Lagerleje | B33: 0 | C33: 0 | D33: 0 | E33: 0 | F33: 0 | G33: 0 | H33: 0 | I33: 0 | J33: 0 | K33: 0 | L33: 0 | M33: 0 | O33: =SUM(B33:M33) -> 0
A34: Vand & varme | B34: 0 | C34: 0 | D34: 0 | E34: 0 | F34: 0 | G34: 0 | H34: 0 | I34: 0 | J34: 0 | K34: 0 | L34: 0 | M34: 0 | O34: =SUM(B34:M34) -> 0
A35: El | B35: 0 | C35: 0 | D35: 0 | E35: 0 | F35: 0 | G35: 0 | H35: 0 | I35: 0 | J35: 0 | K35: 0 | L35: 0 | M35: 0 | O35: =SUM(B35:M35) -> 0
A36: Administrativt
A37: Kontorartikler & møbler | B37: -100 | C37: -100 | D37: -100 | E37: -100 | F37: -100 | G37: -100 | H37: -100 | I37: -100 | J37: -100 | K37: -100 | L37: -100 | M37: -100 | O37: =SUM(B37:M37) -> -1200
A38: IT-udstyr | B38: -1000 | C38: -1000 | D38: -1000 | E38: -1000 | F38: -1000 | G38: -1000 | H38: -1000 | I38: -1000 | J38: -1000 | K38: -1000 | L38: -1000 | M38: -1000 | O38: =SUM(B38:M38) -> -12000
A39: Telefon & Internet | B39: -800 | C39: -800 | D39: -800 | E39: -800 | F39: -800 | G39: -800 | H39: -800 | I39: -800 | J39: -800 | K39: -800 | L39: -800 | M39: -800 | O39: =SUM(B39:M39) -> -9600
A40: Forsikringer | B40: -560 | C40: -560 | D40: -560 | E40: -560 | F40: -560 | G40: -560 | H40: -560 | I40: -560 | J40: -560 | K40: -560 | L40: -560 | M40: -560 | O40: =SUM(B40:M40) -> -6720
A41: Advokat | B41: -1000 | C41: -1000 | D41: -1000 | E41: -1000 | F41: -1000 | G41: -1000 | H41: -1000 | I41: -1000 | J41: -1000 | K41: -1000 | L41: -1000 | M41: -1000 | O41: =SUM(B41:M41) -> -12000
A42: Bogholderi & revision | B42: -8000 | C42: -8000 | D42: -8000 | E42: -8000 | F42: -8000 | G42: -8000 | H42: -8000 | I42: -8000 | J42: -8000 | K42: -8000 | L42: -8000 | M42: -30000 | O42: =SUM(B42:M42) -> -118000
...

Sheet ML tilgodehavende
B1: =PROPER('Opsætning2025'!B$10) -> Januar-25 | C1: =PROPER('Opsætning2025'!C$10) -> Februar-25 | D1: =PROPER('Opsætning2025'!D$10) -> Marts-25 | E1: =PROPER('Opsætning2025'!E$10) -> April-25 | F1: =PROPER('Opsætning2025'!F$10) -> Maj-25 | G1: =PROPER('Opsætning2025'!G$10) -> Juni-25 | H1: =PROPER('Opsætning2025'!H$10) -> Juli-25 | I1: =PROPER('Opsætning2025'!I$10) -> August-25 | ... M1: =PROPER('Opsætning2025'!M$10) -> December-25 | O1: Årstotal
A2: Jonas løn | E2: -18640 | F2: -25000 | G2: -25000 | H2: -35000 | I2: -35000 | J2: -45000 | K2: -45000 | L2: -45000 | M2: -45000 | O2: =SUM(B2:M2) -> -318640
A3: ML konsulent | E3: -18640 | F3: -25000 | G3: -25000 | O3: =SUM(B3:M3) -> -68640

Sheet Indsigt & Overblik
A4: Alle tal er i antal styk | B4: ='Opsætning2025'!B$10 -> januar-25 | C4: ='Opsætning2025'!C$10 -> februar-25 | D4: ='Opsætning2025'!D$10 -> marts-25 | E4: ='Opsætning2025'!E$10 -> april-25 | F4: ='Opsætning2025'!F$10 -> maj-25 | G4: ='Opsætning2025'!G$10 -> juni-25 | H4: ='Opsætning2025'!H$10 -> juli-25 | I4: ='Opsætning2025'!I$10 -> august-25 | ... M4: ='Opsætning2025'!M$10 -> december-25
A5: Ordrer | B5: ='Opsætning2025'!B$13 -> 0 | C5: ='Opsætning2025'!C$13 -> 0 | D5: ='Opsætning2025'!D$13 -> 2 | E5: ='Opsætning2025'!E$13 -> 4 | F5: ='Opsætning2025'!F$13 -> 4 | G5: ='Opsætning2025'!G$13 -> 4 | H5: ='Opsætning2025'!H$13 -> 4 | I5: ='Opsætning2025'!I$13 -> 20 | ... M5: ='Opsætning2025'!M$13 -> 20
A6: Nye kunder | B6: =B5*#REF! -> #REF! | C6: =C5*#REF! -> #REF! | D6: =D5*#REF! -> #REF! | E6: =E5*#REF! -> #REF! | F6: =F5*#REF! -> #REF! | G6: =G5*#REF! -> #REF! | H6: =H5*#REF! -> #REF! | I6: =I5*#REF! -> #REF! | ... M6: =M5*#REF! -> #REF!
A7: Tilbagevendende kunder | B7: =B5*#REF! -> #REF! | C7: =C5*#REF! -> #REF! | D7: =D5*#REF! -> #REF! | E7: =E5*#REF! -> #REF! | F7: =F5*#REF! -> #REF! | G7: =G5*#REF! -> #REF! | H7: =H5*#REF! -> #REF! | I7: =I5*#REF! -> #REF! | ... M7: =M5*#REF! -> #REF!
A8: Gns. køb per kunde

Sheet Marketing

Sheet Fragt & Logistik
